{"timestamp": "2025-04-29T18:14:50.368111", "level": "ERROR", "name": "auth_app", "message": "Function signup failed", "function": "signup", "duration_ms": 258, "error": "module 'datetime' has no attribute 'utcnow'", "success": false, "request_id": "09d03ccd-af2b-4dba-95d8-ccff2c97e49c", "method": "POST", "path": "/auth/signup", "remote_addr": "127.0.0.1", "user_agent": "Werkzeug/3.1.3"}
{"timestamp": "2025-04-29T18:14:50.368635", "level": "ERROR", "name": "auth_app", "message": "Request failed", "error": "module 'datetime' has no attribute 'utcnow'", "request_id": "09d03ccd-af2b-4dba-95d8-ccff2c97e49c", "method": "POST", "path": "/auth/signup", "remote_addr": "127.0.0.1", "user_agent": "Werkzeug/3.1.3"}
{"timestamp": "2025-04-29T18:19:13.044171", "level": "ERROR", "name": "auth_app", "message": "Unexpected error during login", "exc_info": "Traceback (most recent call last):\n  File \"/Users/ek/dev/auth-template/app.py\", line 196, in login\n    data = request.get_json()\n  File \"/Users/ek/dev/auth-template/venv/lib/python3.9/site-packages/werkzeug/wrappers/request.py\", line 604, in get_json\n    return self.on_json_loading_failed(None)\n  File \"/Users/ek/dev/auth-template/venv/lib/python3.9/site-packages/flask/wrappers.py\", line 131, in on_json_loading_failed\n    return super().on_json_loading_failed(e)\n  File \"/Users/ek/dev/auth-template/venv/lib/python3.9/site-packages/werkzeug/wrappers/request.py\", line 647, in on_json_loading_failed\n    raise UnsupportedMediaType(\nwerkzeug.exceptions.UnsupportedMediaType: 415 Unsupported Media Type: Did not attempt to load JSON data because the request Content-Type was not 'application/json'.", "error": "415 Unsupported Media Type: Did not attempt to load JSON data because the request Content-Type was not 'application/json'.", "request_id": "1e8a0be2-99d2-41e4-8a6c-e6fd1e98123a", "method": "POST", "path": "/auth/login", "remote_addr": "127.0.0.1", "user_agent": "Werkzeug/3.1.3"}
{"timestamp": "2025-04-29T18:20:30.364062", "level": "ERROR", "name": "auth_app", "message": "Unexpected error during login", "exc_info": "Traceback (most recent call last):\n  File \"/Users/ek/dev/auth-template/app.py\", line 196, in login\n    data = request.get_json()\n  File \"/Users/ek/dev/auth-template/venv/lib/python3.9/site-packages/werkzeug/wrappers/request.py\", line 604, in get_json\n    return self.on_json_loading_failed(None)\n  File \"/Users/ek/dev/auth-template/venv/lib/python3.9/site-packages/flask/wrappers.py\", line 131, in on_json_loading_failed\n    return super().on_json_loading_failed(e)\n  File \"/Users/ek/dev/auth-template/venv/lib/python3.9/site-packages/werkzeug/wrappers/request.py\", line 647, in on_json_loading_failed\n    raise UnsupportedMediaType(\nwerkzeug.exceptions.UnsupportedMediaType: 415 Unsupported Media Type: Did not attempt to load JSON data because the request Content-Type was not 'application/json'.", "error": "415 Unsupported Media Type: Did not attempt to load JSON data because the request Content-Type was not 'application/json'.", "request_id": "145d56d9-8b7d-4133-85a3-7e0277d3971b", "method": "POST", "path": "/auth/login", "remote_addr": "127.0.0.1", "user_agent": "Werkzeug/3.1.3"}
{"timestamp": "2025-04-29T18:24:19.337454", "level": "ERROR", "name": "auth_app", "message": "Signup failed", "exc_info": "Traceback (most recent call last):\n  File \"/Users/ek/dev/auth-template/app.py\", line 145, in signup\n    email = data['email'].lower().strip()\nAttributeError: 'NoneType' object has no attribute 'lower'", "error": "'NoneType' object has no attribute 'lower'", "request_id": "8003894d-58c9-4301-b033-41ec6864134d", "method": "POST", "path": "/auth/signup", "remote_addr": "127.0.0.1", "user_agent": "Werkzeug/3.1.3"}
{"timestamp": "2025-04-29T18:24:19.481349", "level": "ERROR", "name": "auth_app", "message": "Signup failed", "exc_info": "Traceback (most recent call last):\n  File \"/Users/ek/dev/auth-template/app.py\", line 140, in signup\n    data = request.get_json()\n  File \"/Users/ek/dev/auth-template/venv/lib/python3.9/site-packages/werkzeug/wrappers/request.py\", line 604, in get_json\n    return self.on_json_loading_failed(None)\n  File \"/Users/ek/dev/auth-template/venv/lib/python3.9/site-packages/flask/wrappers.py\", line 131, in on_json_loading_failed\n    return super().on_json_loading_failed(e)\n  File \"/Users/ek/dev/auth-template/venv/lib/python3.9/site-packages/werkzeug/wrappers/request.py\", line 647, in on_json_loading_failed\n    raise UnsupportedMediaType(\nwerkzeug.exceptions.UnsupportedMediaType: 415 Unsupported Media Type: Did not attempt to load JSON data because the request Content-Type was not 'application/json'.", "error": "415 Unsupported Media Type: Did not attempt to load JSON data because the request Content-Type was not 'application/json'.", "request_id": "4d0fdcf0-0087-4c1e-855d-88ba29b3305c", "method": "POST", "path": "/auth/signup", "remote_addr": "127.0.0.1", "user_agent": "Werkzeug/3.1.3"}
{"timestamp": "2025-04-29T18:24:19.793543", "level": "ERROR", "name": "auth_app", "message": "Unexpected error during login", "exc_info": "Traceback (most recent call last):\n  File \"/Users/ek/dev/auth-template/app.py\", line 199, in login\n    data = request.get_json()\n  File \"/Users/ek/dev/auth-template/venv/lib/python3.9/site-packages/werkzeug/wrappers/request.py\", line 604, in get_json\n    return self.on_json_loading_failed(None)\n  File \"/Users/ek/dev/auth-template/venv/lib/python3.9/site-packages/flask/wrappers.py\", line 131, in on_json_loading_failed\n    return super().on_json_loading_failed(e)\n  File \"/Users/ek/dev/auth-template/venv/lib/python3.9/site-packages/werkzeug/wrappers/request.py\", line 647, in on_json_loading_failed\n    raise UnsupportedMediaType(\nwerkzeug.exceptions.UnsupportedMediaType: 415 Unsupported Media Type: Did not attempt to load JSON data because the request Content-Type was not 'application/json'.", "error": "415 Unsupported Media Type: Did not attempt to load JSON data because the request Content-Type was not 'application/json'.", "request_id": "19533e15-782c-4db2-872c-f98c13fb04fa", "method": "POST", "path": "/auth/login", "remote_addr": "127.0.0.1", "user_agent": "Werkzeug/3.1.3"}
{"timestamp": "2025-04-29T18:24:19.807211", "level": "ERROR", "name": "auth_app", "message": "Unexpected error during login", "exc_info": "Traceback (most recent call last):\n  File \"/Users/ek/dev/auth-template/app.py\", line 199, in login\n    data = request.get_json()\n  File \"/Users/ek/dev/auth-template/venv/lib/python3.9/site-packages/werkzeug/wrappers/request.py\", line 604, in get_json\n    return self.on_json_loading_failed(None)\n  File \"/Users/ek/dev/auth-template/venv/lib/python3.9/site-packages/flask/wrappers.py\", line 131, in on_json_loading_failed\n    return super().on_json_loading_failed(e)\n  File \"/Users/ek/dev/auth-template/venv/lib/python3.9/site-packages/werkzeug/wrappers/request.py\", line 647, in on_json_loading_failed\n    raise UnsupportedMediaType(\nwerkzeug.exceptions.UnsupportedMediaType: 415 Unsupported Media Type: Did not attempt to load JSON data because the request Content-Type was not 'application/json'.", "error": "415 Unsupported Media Type: Did not attempt to load JSON data because the request Content-Type was not 'application/json'.", "request_id": "6d31eb10-904e-4c45-afc1-ce9438fac8ad", "method": "POST", "path": "/auth/login", "remote_addr": "127.0.0.1", "user_agent": "Werkzeug/3.1.3"}
{"timestamp": "2025-04-29T18:28:55.949137", "level": "ERROR", "name": "auth_app", "message": "Unexpected error during login", "exc_info": "Traceback (most recent call last):\n  File \"/Users/ek/dev/auth-template/app.py\", line 256, in login\n    'exp': datetime.datetime.utcnow() + datetime.timedelta(hours=1),  # Short expiration time\nAttributeError: type object 'datetime.datetime' has no attribute 'datetime'", "error": "type object 'datetime.datetime' has no attribute 'datetime'", "request_id": "8bc0f723-96fb-4de2-af82-2150f1043688", "method": "POST", "path": "/auth/login", "remote_addr": "127.0.0.1", "user_agent": "Werkzeug/3.1.3"}
{"timestamp": "2025-04-29T18:28:56.510444", "level": "ERROR", "name": "auth_app", "message": "Unexpected error during login", "exc_info": "Traceback (most recent call last):\n  File \"/Users/ek/dev/auth-template/app.py\", line 240, in login\n    user['last_failed_attempt'] = datetime.datetime.utcnow()\nAttributeError: type object 'datetime.datetime' has no attribute 'datetime'", "error": "type object 'datetime.datetime' has no attribute 'datetime'", "request_id": "d49f11d2-fa58-44be-9aea-f067c0aad94e", "method": "POST", "path": "/auth/login", "remote_addr": "127.0.0.1", "user_agent": "Werkzeug/3.1.3"}
{"timestamp": "2025-04-29T18:28:56.784932", "level": "ERROR", "name": "auth_app", "message": "Unexpected error during login", "exc_info": "Traceback (most recent call last):\n  File \"/Users/ek/dev/auth-template/app.py\", line 199, in login\n    data = request.get_json()\n  File \"/Users/ek/dev/auth-template/venv/lib/python3.9/site-packages/werkzeug/wrappers/request.py\", line 604, in get_json\n    return self.on_json_loading_failed(None)\n  File \"/Users/ek/dev/auth-template/venv/lib/python3.9/site-packages/flask/wrappers.py\", line 131, in on_json_loading_failed\n    return super().on_json_loading_failed(e)\n  File \"/Users/ek/dev/auth-template/venv/lib/python3.9/site-packages/werkzeug/wrappers/request.py\", line 647, in on_json_loading_failed\n    raise UnsupportedMediaType(\nwerkzeug.exceptions.UnsupportedMediaType: 415 Unsupported Media Type: Did not attempt to load JSON data because the request Content-Type was not 'application/json'.", "error": "415 Unsupported Media Type: Did not attempt to load JSON data because the request Content-Type was not 'application/json'.", "request_id": "9fbec195-d1ea-414a-aadb-c76b4ff6b214", "method": "POST", "path": "/auth/login", "remote_addr": "127.0.0.1", "user_agent": "Werkzeug/3.1.3"}
{"timestamp": "2025-04-29T18:30:10.606130", "level": "ERROR", "name": "auth_app", "message": "Unexpected error during login", "exc_info": "Traceback (most recent call last):\n  File \"/Users/ek/dev/auth-template/venv/lib/python3.9/site-packages/werkzeug/wrappers/request.py\", line 611, in get_json\n    rv = self.json_module.loads(data)\n  File \"/Users/ek/dev/auth-template/venv/lib/python3.9/site-packages/flask/json/provider.py\", line 187, in loads\n    return json.loads(s, **kwargs)\n  File \"/Library/Developer/CommandLineTools/Library/Frameworks/Python3.framework/Versions/3.9/lib/python3.9/json/__init__.py\", line 346, in loads\n    return _default_decoder.decode(s)\n  File \"/Library/Developer/CommandLineTools/Library/Frameworks/Python3.framework/Versions/3.9/lib/python3.9/json/decoder.py\", line 337, in decode\n    obj, end = self.raw_decode(s, idx=_w(s, 0).end())\n  File \"/Library/Developer/CommandLineTools/Library/Frameworks/Python3.framework/Versions/3.9/lib/python3.9/json/decoder.py\", line 355, in raw_decode\n    raise JSONDecodeError(\"Expecting value\", s, err.value) from None\njson.decoder.JSONDecodeError: Expecting value: line 1 column 1 (char 0)\n\nDuring handling of the above exception, another exception occurred:\n\nTraceback (most recent call last):\n  File \"/Users/ek/dev/auth-template/app.py\", line 199, in login\n    data = request.get_json()\n  File \"/Users/ek/dev/auth-template/venv/lib/python3.9/site-packages/werkzeug/wrappers/request.py\", line 620, in get_json\n    rv = self.on_json_loading_failed(e)\n  File \"/Users/ek/dev/auth-template/venv/lib/python3.9/site-packages/flask/wrappers.py\", line 131, in on_json_loading_failed\n    return super().on_json_loading_failed(e)\n  File \"/Users/ek/dev/auth-template/venv/lib/python3.9/site-packages/werkzeug/wrappers/request.py\", line 645, in on_json_loading_failed\n    raise BadRequest(f\"Failed to decode JSON object: {e}\")\nwerkzeug.exceptions.BadRequest: 400 Bad Request: Failed to decode JSON object: Expecting value: line 1 column 1 (char 0)", "error": "400 Bad Request: Failed to decode JSON object: Expecting value: line 1 column 1 (char 0)", "request_id": "71fcf01c-d61a-4a50-88d1-2efb1da62e06", "method": "POST", "path": "/auth/login", "remote_addr": "127.0.0.1", "user_agent": "Werkzeug/3.1.3"}
{"timestamp": "2025-04-29T18:57:00.380590", "level": "ERROR", "name": "auth_app", "message": "Signup failed", "exc_info": "Traceback (most recent call last):\n  File \"/Users/ek/dev/auth-template/venv/lib/python3.9/site-packages/werkzeug/wrappers/request.py\", line 611, in get_json\n    rv = self.json_module.loads(data)\n  File \"/Users/ek/dev/auth-template/venv/lib/python3.9/site-packages/flask/json/provider.py\", line 187, in loads\n    return json.loads(s, **kwargs)\n  File \"/Library/Developer/CommandLineTools/Library/Frameworks/Python3.framework/Versions/3.9/lib/python3.9/json/__init__.py\", line 346, in loads\n    return _default_decoder.decode(s)\n  File \"/Library/Developer/CommandLineTools/Library/Frameworks/Python3.framework/Versions/3.9/lib/python3.9/json/decoder.py\", line 337, in decode\n    obj, end = self.raw_decode(s, idx=_w(s, 0).end())\n  File \"/Library/Developer/CommandLineTools/Library/Frameworks/Python3.framework/Versions/3.9/lib/python3.9/json/decoder.py\", line 355, in raw_decode\n    raise JSONDecodeError(\"Expecting value\", s, err.value) from None\njson.decoder.JSONDecodeError: Expecting value: line 1 column 1 (char 0)\n\nDuring handling of the above exception, another exception occurred:\n\nTraceback (most recent call last):\n  File \"/Users/ek/dev/auth-template/app.py\", line 141, in signup\n    data = request.get_json()\n  File \"/Users/ek/dev/auth-template/venv/lib/python3.9/site-packages/werkzeug/wrappers/request.py\", line 620, in get_json\n    rv = self.on_json_loading_failed(e)\n  File \"/Users/ek/dev/auth-template/venv/lib/python3.9/site-packages/flask/wrappers.py\", line 131, in on_json_loading_failed\n    return super().on_json_loading_failed(e)\n  File \"/Users/ek/dev/auth-template/venv/lib/python3.9/site-packages/werkzeug/wrappers/request.py\", line 645, in on_json_loading_failed\n    raise BadRequest(f\"Failed to decode JSON object: {e}\")\nwerkzeug.exceptions.BadRequest: 400 Bad Request: Failed to decode JSON object: Expecting value: line 1 column 1 (char 0)", "error": "400 Bad Request: Failed to decode JSON object: Expecting value: line 1 column 1 (char 0)", "request_id": "4354cb7c-baa1-44b7-86b3-f4a67d262be7", "method": "POST", "path": "/auth/signup", "remote_addr": "127.0.0.1", "user_agent": "Werkzeug/3.1.3"}
{"timestamp": "2025-04-29T21:30:13.050128", "level": "ERROR", "name": "auth_app", "message": "Signup failed", "exc_info": "Traceback (most recent call last):\n  File \"/Users/ek/dev/auth-template/api/services/auth_service.py\", line 17, in signup\n    is_valid, error_message = ValidationService.validate_signup_input(email, password, confirm_password)\n  File \"/Users/ek/dev/auth-template/api/services/validation_service.py\", line 61, in validate_signup_input\n    existing_user = User.query.filter(User.email.ilike(email)).first()\n  File \"/Users/ek/dev/auth-template/venv/lib/python3.9/site-packages/sqlalchemy/orm/query.py\", line 2759, in first\n    return self.limit(1)._iter().first()  # type: ignore\n  File \"/Users/ek/dev/auth-template/venv/lib/python3.9/site-packages/sqlalchemy/orm/query.py\", line 2858, in _iter\n    result: Union[ScalarResult[_T], Result[_T]] = self.session.execute(\n  File \"/Users/ek/dev/auth-template/venv/lib/python3.9/site-packages/sqlalchemy/orm/session.py\", line 2365, in execute\n    return self._execute_internal(\n  File \"/Users/ek/dev/auth-template/venv/lib/python3.9/site-packages/sqlalchemy/orm/session.py\", line 2239, in _execute_internal\n    bind = self.get_bind(**bind_arguments)\n  File \"/Users/ek/dev/auth-template/venv/lib/python3.9/site-packages/flask_sqlalchemy/session.py\", line 53, in get_bind\n    engines = self._db.engines\n  File \"/Users/ek/dev/auth-template/venv/lib/python3.9/site-packages/flask_sqlalchemy/extension.py\", line 690, in engines\n    raise RuntimeError(\nRuntimeError: The current Flask app is not registered with this 'SQLAlchemy' instance. Did you forget to call 'init_app', or did you create multiple 'SQLAlchemy' instances?", "error": "The current Flask app is not registered with this 'SQLAlchemy' instance. Did you forget to call 'init_app', or did you create multiple 'SQLAlchemy' instances?", "request_id": "2aaa1271-bd9b-4196-924d-03cfee353a63", "method": "POST", "path": "/api/auth/signup", "remote_addr": "127.0.0.1", "user_agent": "Werkzeug/3.1.3"}
{"timestamp": "2025-04-29T21:30:13.059419", "level": "ERROR", "name": "auth_app", "message": "Login failed", "exc_info": "Traceback (most recent call last):\n  File \"/Users/ek/dev/auth-template/api/services/auth_service.py\", line 51, in login\n    user = User.query.filter(User.email.ilike(email)).first()\n  File \"/Users/ek/dev/auth-template/venv/lib/python3.9/site-packages/sqlalchemy/orm/query.py\", line 2759, in first\n    return self.limit(1)._iter().first()  # type: ignore\n  File \"/Users/ek/dev/auth-template/venv/lib/python3.9/site-packages/sqlalchemy/orm/query.py\", line 2858, in _iter\n    result: Union[ScalarResult[_T], Result[_T]] = self.session.execute(\n  File \"/Users/ek/dev/auth-template/venv/lib/python3.9/site-packages/sqlalchemy/orm/session.py\", line 2365, in execute\n    return self._execute_internal(\n  File \"/Users/ek/dev/auth-template/venv/lib/python3.9/site-packages/sqlalchemy/orm/session.py\", line 2239, in _execute_internal\n    bind = self.get_bind(**bind_arguments)\n  File \"/Users/ek/dev/auth-template/venv/lib/python3.9/site-packages/flask_sqlalchemy/session.py\", line 53, in get_bind\n    engines = self._db.engines\n  File \"/Users/ek/dev/auth-template/venv/lib/python3.9/site-packages/flask_sqlalchemy/extension.py\", line 690, in engines\n    raise RuntimeError(\nRuntimeError: The current Flask app is not registered with this 'SQLAlchemy' instance. Did you forget to call 'init_app', or did you create multiple 'SQLAlchemy' instances?", "error": "The current Flask app is not registered with this 'SQLAlchemy' instance. Did you forget to call 'init_app', or did you create multiple 'SQLAlchemy' instances?", "request_id": "6c7d4e03-32ba-4f4d-8a7b-ae0cc39d49fa", "method": "POST", "path": "/api/auth/login", "remote_addr": "127.0.0.1", "user_agent": "Werkzeug/3.1.3"}
{"timestamp": "2025-04-29T21:30:13.126697", "level": "ERROR", "name": "auth_app", "message": "Signup failed", "exc_info": "Traceback (most recent call last):\n  File \"/Users/ek/dev/auth-template/api/services/auth_service.py\", line 17, in signup\n    is_valid, error_message = ValidationService.validate_signup_input(email, password, confirm_password)\n  File \"/Users/ek/dev/auth-template/api/services/validation_service.py\", line 61, in validate_signup_input\n    existing_user = User.query.filter(User.email.ilike(email)).first()\n  File \"/Users/ek/dev/auth-template/venv/lib/python3.9/site-packages/sqlalchemy/orm/query.py\", line 2759, in first\n    return self.limit(1)._iter().first()  # type: ignore\n  File \"/Users/ek/dev/auth-template/venv/lib/python3.9/site-packages/sqlalchemy/orm/query.py\", line 2858, in _iter\n    result: Union[ScalarResult[_T], Result[_T]] = self.session.execute(\n  File \"/Users/ek/dev/auth-template/venv/lib/python3.9/site-packages/sqlalchemy/orm/session.py\", line 2365, in execute\n    return self._execute_internal(\n  File \"/Users/ek/dev/auth-template/venv/lib/python3.9/site-packages/sqlalchemy/orm/session.py\", line 2239, in _execute_internal\n    bind = self.get_bind(**bind_arguments)\n  File \"/Users/ek/dev/auth-template/venv/lib/python3.9/site-packages/flask_sqlalchemy/session.py\", line 53, in get_bind\n    engines = self._db.engines\n  File \"/Users/ek/dev/auth-template/venv/lib/python3.9/site-packages/flask_sqlalchemy/extension.py\", line 690, in engines\n    raise RuntimeError(\nRuntimeError: The current Flask app is not registered with this 'SQLAlchemy' instance. Did you forget to call 'init_app', or did you create multiple 'SQLAlchemy' instances?", "error": "The current Flask app is not registered with this 'SQLAlchemy' instance. Did you forget to call 'init_app', or did you create multiple 'SQLAlchemy' instances?", "request_id": "e688bf42-98b6-4338-8bea-aaf638ab6d4f", "method": "POST", "path": "/api/auth/signup", "remote_addr": "127.0.0.1", "user_agent": "Werkzeug/3.1.3"}
{"timestamp": "2025-04-29T21:30:13.137251", "level": "ERROR", "name": "auth_app", "message": "Login failed", "exc_info": "Traceback (most recent call last):\n  File \"/Users/ek/dev/auth-template/api/services/auth_service.py\", line 51, in login\n    user = User.query.filter(User.email.ilike(email)).first()\n  File \"/Users/ek/dev/auth-template/venv/lib/python3.9/site-packages/sqlalchemy/orm/query.py\", line 2759, in first\n    return self.limit(1)._iter().first()  # type: ignore\n  File \"/Users/ek/dev/auth-template/venv/lib/python3.9/site-packages/sqlalchemy/orm/query.py\", line 2858, in _iter\n    result: Union[ScalarResult[_T], Result[_T]] = self.session.execute(\n  File \"/Users/ek/dev/auth-template/venv/lib/python3.9/site-packages/sqlalchemy/orm/session.py\", line 2365, in execute\n    return self._execute_internal(\n  File \"/Users/ek/dev/auth-template/venv/lib/python3.9/site-packages/sqlalchemy/orm/session.py\", line 2239, in _execute_internal\n    bind = self.get_bind(**bind_arguments)\n  File \"/Users/ek/dev/auth-template/venv/lib/python3.9/site-packages/flask_sqlalchemy/session.py\", line 53, in get_bind\n    engines = self._db.engines\n  File \"/Users/ek/dev/auth-template/venv/lib/python3.9/site-packages/flask_sqlalchemy/extension.py\", line 690, in engines\n    raise RuntimeError(\nRuntimeError: The current Flask app is not registered with this 'SQLAlchemy' instance. Did you forget to call 'init_app', or did you create multiple 'SQLAlchemy' instances?", "error": "The current Flask app is not registered with this 'SQLAlchemy' instance. Did you forget to call 'init_app', or did you create multiple 'SQLAlchemy' instances?", "request_id": "dd31cf95-c14a-4c59-9452-cfcd6d4c0567", "method": "POST", "path": "/api/auth/login", "remote_addr": "127.0.0.1", "user_agent": "Werkzeug/3.1.3"}
{"timestamp": "2025-04-29T21:30:13.167034", "level": "ERROR", "name": "auth_app", "message": "Login failed", "exc_info": "Traceback (most recent call last):\n  File \"/Users/ek/dev/auth-template/api/services/auth_service.py\", line 51, in login\n    user = User.query.filter(User.email.ilike(email)).first()\n  File \"/Users/ek/dev/auth-template/venv/lib/python3.9/site-packages/sqlalchemy/orm/query.py\", line 2759, in first\n    return self.limit(1)._iter().first()  # type: ignore\n  File \"/Users/ek/dev/auth-template/venv/lib/python3.9/site-packages/sqlalchemy/orm/query.py\", line 2858, in _iter\n    result: Union[ScalarResult[_T], Result[_T]] = self.session.execute(\n  File \"/Users/ek/dev/auth-template/venv/lib/python3.9/site-packages/sqlalchemy/orm/session.py\", line 2365, in execute\n    return self._execute_internal(\n  File \"/Users/ek/dev/auth-template/venv/lib/python3.9/site-packages/sqlalchemy/orm/session.py\", line 2239, in _execute_internal\n    bind = self.get_bind(**bind_arguments)\n  File \"/Users/ek/dev/auth-template/venv/lib/python3.9/site-packages/flask_sqlalchemy/session.py\", line 53, in get_bind\n    engines = self._db.engines\n  File \"/Users/ek/dev/auth-template/venv/lib/python3.9/site-packages/flask_sqlalchemy/extension.py\", line 690, in engines\n    raise RuntimeError(\nRuntimeError: The current Flask app is not registered with this 'SQLAlchemy' instance. Did you forget to call 'init_app', or did you create multiple 'SQLAlchemy' instances?", "error": "The current Flask app is not registered with this 'SQLAlchemy' instance. Did you forget to call 'init_app', or did you create multiple 'SQLAlchemy' instances?", "request_id": "baf602a4-f927-407f-aea6-f1165dd9b784", "method": "POST", "path": "/api/auth/login", "remote_addr": "127.0.0.1", "user_agent": "Werkzeug/3.1.3"}
{"timestamp": "2025-04-29T21:30:13.198500", "level": "ERROR", "name": "auth_app", "message": "Signup failed", "exc_info": "Traceback (most recent call last):\n  File \"/Users/ek/dev/auth-template/api/services/auth_service.py\", line 17, in signup\n    is_valid, error_message = ValidationService.validate_signup_input(email, password, confirm_password)\n  File \"/Users/ek/dev/auth-template/api/services/validation_service.py\", line 61, in validate_signup_input\n    existing_user = User.query.filter(User.email.ilike(email)).first()\n  File \"/Users/ek/dev/auth-template/venv/lib/python3.9/site-packages/sqlalchemy/orm/query.py\", line 2759, in first\n    return self.limit(1)._iter().first()  # type: ignore\n  File \"/Users/ek/dev/auth-template/venv/lib/python3.9/site-packages/sqlalchemy/orm/query.py\", line 2858, in _iter\n    result: Union[ScalarResult[_T], Result[_T]] = self.session.execute(\n  File \"/Users/ek/dev/auth-template/venv/lib/python3.9/site-packages/sqlalchemy/orm/session.py\", line 2365, in execute\n    return self._execute_internal(\n  File \"/Users/ek/dev/auth-template/venv/lib/python3.9/site-packages/sqlalchemy/orm/session.py\", line 2239, in _execute_internal\n    bind = self.get_bind(**bind_arguments)\n  File \"/Users/ek/dev/auth-template/venv/lib/python3.9/site-packages/flask_sqlalchemy/session.py\", line 53, in get_bind\n    engines = self._db.engines\n  File \"/Users/ek/dev/auth-template/venv/lib/python3.9/site-packages/flask_sqlalchemy/extension.py\", line 690, in engines\n    raise RuntimeError(\nRuntimeError: The current Flask app is not registered with this 'SQLAlchemy' instance. Did you forget to call 'init_app', or did you create multiple 'SQLAlchemy' instances?", "error": "The current Flask app is not registered with this 'SQLAlchemy' instance. Did you forget to call 'init_app', or did you create multiple 'SQLAlchemy' instances?", "request_id": "48ffe763-bb5e-413b-9a74-47ca4ebeae4f", "method": "POST", "path": "/api/auth/signup", "remote_addr": "127.0.0.1", "user_agent": "Werkzeug/3.1.3"}
{"timestamp": "2025-04-29T21:30:13.204798", "level": "ERROR", "name": "auth_app", "message": "Login failed", "exc_info": "Traceback (most recent call last):\n  File \"/Users/ek/dev/auth-template/api/services/auth_service.py\", line 51, in login\n    user = User.query.filter(User.email.ilike(email)).first()\n  File \"/Users/ek/dev/auth-template/venv/lib/python3.9/site-packages/sqlalchemy/orm/query.py\", line 2759, in first\n    return self.limit(1)._iter().first()  # type: ignore\n  File \"/Users/ek/dev/auth-template/venv/lib/python3.9/site-packages/sqlalchemy/orm/query.py\", line 2858, in _iter\n    result: Union[ScalarResult[_T], Result[_T]] = self.session.execute(\n  File \"/Users/ek/dev/auth-template/venv/lib/python3.9/site-packages/sqlalchemy/orm/session.py\", line 2365, in execute\n    return self._execute_internal(\n  File \"/Users/ek/dev/auth-template/venv/lib/python3.9/site-packages/sqlalchemy/orm/session.py\", line 2239, in _execute_internal\n    bind = self.get_bind(**bind_arguments)\n  File \"/Users/ek/dev/auth-template/venv/lib/python3.9/site-packages/flask_sqlalchemy/session.py\", line 53, in get_bind\n    engines = self._db.engines\n  File \"/Users/ek/dev/auth-template/venv/lib/python3.9/site-packages/flask_sqlalchemy/extension.py\", line 690, in engines\n    raise RuntimeError(\nRuntimeError: The current Flask app is not registered with this 'SQLAlchemy' instance. Did you forget to call 'init_app', or did you create multiple 'SQLAlchemy' instances?", "error": "The current Flask app is not registered with this 'SQLAlchemy' instance. Did you forget to call 'init_app', or did you create multiple 'SQLAlchemy' instances?", "request_id": "8aabf503-cee0-4e90-857f-1ffb8093bb12", "method": "POST", "path": "/api/auth/login", "remote_addr": "127.0.0.1", "user_agent": "Werkzeug/3.1.3"}
{"timestamp": "2025-04-29T21:30:13.251163", "level": "ERROR", "name": "auth_app", "message": "Signup failed", "exc_info": "Traceback (most recent call last):\n  File \"/Users/ek/dev/auth-template/api/services/auth_service.py\", line 17, in signup\n    is_valid, error_message = ValidationService.validate_signup_input(email, password, confirm_password)\n  File \"/Users/ek/dev/auth-template/api/services/validation_service.py\", line 61, in validate_signup_input\n    existing_user = User.query.filter(User.email.ilike(email)).first()\n  File \"/Users/ek/dev/auth-template/venv/lib/python3.9/site-packages/sqlalchemy/orm/query.py\", line 2759, in first\n    return self.limit(1)._iter().first()  # type: ignore\n  File \"/Users/ek/dev/auth-template/venv/lib/python3.9/site-packages/sqlalchemy/orm/query.py\", line 2858, in _iter\n    result: Union[ScalarResult[_T], Result[_T]] = self.session.execute(\n  File \"/Users/ek/dev/auth-template/venv/lib/python3.9/site-packages/sqlalchemy/orm/session.py\", line 2365, in execute\n    return self._execute_internal(\n  File \"/Users/ek/dev/auth-template/venv/lib/python3.9/site-packages/sqlalchemy/orm/session.py\", line 2239, in _execute_internal\n    bind = self.get_bind(**bind_arguments)\n  File \"/Users/ek/dev/auth-template/venv/lib/python3.9/site-packages/flask_sqlalchemy/session.py\", line 53, in get_bind\n    engines = self._db.engines\n  File \"/Users/ek/dev/auth-template/venv/lib/python3.9/site-packages/flask_sqlalchemy/extension.py\", line 690, in engines\n    raise RuntimeError(\nRuntimeError: The current Flask app is not registered with this 'SQLAlchemy' instance. Did you forget to call 'init_app', or did you create multiple 'SQLAlchemy' instances?", "error": "The current Flask app is not registered with this 'SQLAlchemy' instance. Did you forget to call 'init_app', or did you create multiple 'SQLAlchemy' instances?", "request_id": "f1c9ffde-149f-4e9c-b6a1-fe8bd58a3bc2", "method": "POST", "path": "/api/auth/signup", "remote_addr": "127.0.0.1", "user_agent": "Werkzeug/3.1.3"}
{"timestamp": "2025-04-29T21:30:13.258751", "level": "ERROR", "name": "auth_app", "message": "Login failed", "exc_info": "Traceback (most recent call last):\n  File \"/Users/ek/dev/auth-template/api/services/auth_service.py\", line 51, in login\n    user = User.query.filter(User.email.ilike(email)).first()\n  File \"/Users/ek/dev/auth-template/venv/lib/python3.9/site-packages/sqlalchemy/orm/query.py\", line 2759, in first\n    return self.limit(1)._iter().first()  # type: ignore\n  File \"/Users/ek/dev/auth-template/venv/lib/python3.9/site-packages/sqlalchemy/orm/query.py\", line 2858, in _iter\n    result: Union[ScalarResult[_T], Result[_T]] = self.session.execute(\n  File \"/Users/ek/dev/auth-template/venv/lib/python3.9/site-packages/sqlalchemy/orm/session.py\", line 2365, in execute\n    return self._execute_internal(\n  File \"/Users/ek/dev/auth-template/venv/lib/python3.9/site-packages/sqlalchemy/orm/session.py\", line 2239, in _execute_internal\n    bind = self.get_bind(**bind_arguments)\n  File \"/Users/ek/dev/auth-template/venv/lib/python3.9/site-packages/flask_sqlalchemy/session.py\", line 53, in get_bind\n    engines = self._db.engines\n  File \"/Users/ek/dev/auth-template/venv/lib/python3.9/site-packages/flask_sqlalchemy/extension.py\", line 690, in engines\n    raise RuntimeError(\nRuntimeError: The current Flask app is not registered with this 'SQLAlchemy' instance. Did you forget to call 'init_app', or did you create multiple 'SQLAlchemy' instances?", "error": "The current Flask app is not registered with this 'SQLAlchemy' instance. Did you forget to call 'init_app', or did you create multiple 'SQLAlchemy' instances?", "request_id": "3d9f34ec-08e4-4d78-9334-d619a5521e62", "method": "POST", "path": "/api/auth/login", "remote_addr": "127.0.0.1", "user_agent": "Werkzeug/3.1.3"}
{"timestamp": "2025-04-29T21:30:13.297557", "level": "ERROR", "name": "auth_app", "message": "Signup failed", "exc_info": "Traceback (most recent call last):\n  File \"/Users/ek/dev/auth-template/api/services/auth_service.py\", line 17, in signup\n    is_valid, error_message = ValidationService.validate_signup_input(email, password, confirm_password)\n  File \"/Users/ek/dev/auth-template/api/services/validation_service.py\", line 61, in validate_signup_input\n    existing_user = User.query.filter(User.email.ilike(email)).first()\n  File \"/Users/ek/dev/auth-template/venv/lib/python3.9/site-packages/sqlalchemy/orm/query.py\", line 2759, in first\n    return self.limit(1)._iter().first()  # type: ignore\n  File \"/Users/ek/dev/auth-template/venv/lib/python3.9/site-packages/sqlalchemy/orm/query.py\", line 2858, in _iter\n    result: Union[ScalarResult[_T], Result[_T]] = self.session.execute(\n  File \"/Users/ek/dev/auth-template/venv/lib/python3.9/site-packages/sqlalchemy/orm/session.py\", line 2365, in execute\n    return self._execute_internal(\n  File \"/Users/ek/dev/auth-template/venv/lib/python3.9/site-packages/sqlalchemy/orm/session.py\", line 2239, in _execute_internal\n    bind = self.get_bind(**bind_arguments)\n  File \"/Users/ek/dev/auth-template/venv/lib/python3.9/site-packages/flask_sqlalchemy/session.py\", line 53, in get_bind\n    engines = self._db.engines\n  File \"/Users/ek/dev/auth-template/venv/lib/python3.9/site-packages/flask_sqlalchemy/extension.py\", line 690, in engines\n    raise RuntimeError(\nRuntimeError: The current Flask app is not registered with this 'SQLAlchemy' instance. Did you forget to call 'init_app', or did you create multiple 'SQLAlchemy' instances?", "error": "The current Flask app is not registered with this 'SQLAlchemy' instance. Did you forget to call 'init_app', or did you create multiple 'SQLAlchemy' instances?", "request_id": "92e44e2d-9de8-4c0f-93ee-365484eac517", "method": "POST", "path": "/api/auth/signup", "remote_addr": "127.0.0.1", "user_agent": "Werkzeug/3.1.3"}
{"timestamp": "2025-04-29T21:30:13.392097", "level": "ERROR", "name": "auth_app", "message": "Signup failed", "exc_info": "Traceback (most recent call last):\n  File \"/Users/ek/dev/auth-template/api/services/auth_service.py\", line 17, in signup\n    is_valid, error_message = ValidationService.validate_signup_input(email, password, confirm_password)\n  File \"/Users/ek/dev/auth-template/api/services/validation_service.py\", line 61, in validate_signup_input\n    existing_user = User.query.filter(User.email.ilike(email)).first()\n  File \"/Users/ek/dev/auth-template/venv/lib/python3.9/site-packages/sqlalchemy/orm/query.py\", line 2759, in first\n    return self.limit(1)._iter().first()  # type: ignore\n  File \"/Users/ek/dev/auth-template/venv/lib/python3.9/site-packages/sqlalchemy/orm/query.py\", line 2858, in _iter\n    result: Union[ScalarResult[_T], Result[_T]] = self.session.execute(\n  File \"/Users/ek/dev/auth-template/venv/lib/python3.9/site-packages/sqlalchemy/orm/session.py\", line 2365, in execute\n    return self._execute_internal(\n  File \"/Users/ek/dev/auth-template/venv/lib/python3.9/site-packages/sqlalchemy/orm/session.py\", line 2239, in _execute_internal\n    bind = self.get_bind(**bind_arguments)\n  File \"/Users/ek/dev/auth-template/venv/lib/python3.9/site-packages/flask_sqlalchemy/session.py\", line 53, in get_bind\n    engines = self._db.engines\n  File \"/Users/ek/dev/auth-template/venv/lib/python3.9/site-packages/flask_sqlalchemy/extension.py\", line 690, in engines\n    raise RuntimeError(\nRuntimeError: The current Flask app is not registered with this 'SQLAlchemy' instance. Did you forget to call 'init_app', or did you create multiple 'SQLAlchemy' instances?", "error": "The current Flask app is not registered with this 'SQLAlchemy' instance. Did you forget to call 'init_app', or did you create multiple 'SQLAlchemy' instances?", "request_id": "82fbec5c-4588-4e66-938a-7c3a60289504", "method": "POST", "path": "/api/auth/signup", "remote_addr": "127.0.0.1", "user_agent": "Werkzeug/3.1.3"}
{"timestamp": "2025-04-29T21:30:13.418224", "level": "ERROR", "name": "auth_app", "message": "Signup failed", "exc_info": "Traceback (most recent call last):\n  File \"/Users/ek/dev/auth-template/api/services/auth_service.py\", line 17, in signup\n    is_valid, error_message = ValidationService.validate_signup_input(email, password, confirm_password)\n  File \"/Users/ek/dev/auth-template/api/services/validation_service.py\", line 61, in validate_signup_input\n    existing_user = User.query.filter(User.email.ilike(email)).first()\n  File \"/Users/ek/dev/auth-template/venv/lib/python3.9/site-packages/sqlalchemy/orm/query.py\", line 2759, in first\n    return self.limit(1)._iter().first()  # type: ignore\n  File \"/Users/ek/dev/auth-template/venv/lib/python3.9/site-packages/sqlalchemy/orm/query.py\", line 2858, in _iter\n    result: Union[ScalarResult[_T], Result[_T]] = self.session.execute(\n  File \"/Users/ek/dev/auth-template/venv/lib/python3.9/site-packages/sqlalchemy/orm/session.py\", line 2365, in execute\n    return self._execute_internal(\n  File \"/Users/ek/dev/auth-template/venv/lib/python3.9/site-packages/sqlalchemy/orm/session.py\", line 2239, in _execute_internal\n    bind = self.get_bind(**bind_arguments)\n  File \"/Users/ek/dev/auth-template/venv/lib/python3.9/site-packages/flask_sqlalchemy/session.py\", line 53, in get_bind\n    engines = self._db.engines\n  File \"/Users/ek/dev/auth-template/venv/lib/python3.9/site-packages/flask_sqlalchemy/extension.py\", line 690, in engines\n    raise RuntimeError(\nRuntimeError: The current Flask app is not registered with this 'SQLAlchemy' instance. Did you forget to call 'init_app', or did you create multiple 'SQLAlchemy' instances?", "error": "The current Flask app is not registered with this 'SQLAlchemy' instance. Did you forget to call 'init_app', or did you create multiple 'SQLAlchemy' instances?", "request_id": "30ed0fa7-a5c6-4533-b2f2-8a205c34d7a4", "method": "POST", "path": "/api/auth/signup", "remote_addr": "127.0.0.1", "user_agent": "Werkzeug/3.1.3"}
{"timestamp": "2025-04-29T21:30:13.446158", "level": "ERROR", "name": "auth_app", "message": "Signup failed", "exc_info": "Traceback (most recent call last):\n  File \"/Users/ek/dev/auth-template/api/services/auth_service.py\", line 17, in signup\n    is_valid, error_message = ValidationService.validate_signup_input(email, password, confirm_password)\n  File \"/Users/ek/dev/auth-template/api/services/validation_service.py\", line 61, in validate_signup_input\n    existing_user = User.query.filter(User.email.ilike(email)).first()\n  File \"/Users/ek/dev/auth-template/venv/lib/python3.9/site-packages/sqlalchemy/orm/query.py\", line 2759, in first\n    return self.limit(1)._iter().first()  # type: ignore\n  File \"/Users/ek/dev/auth-template/venv/lib/python3.9/site-packages/sqlalchemy/orm/query.py\", line 2858, in _iter\n    result: Union[ScalarResult[_T], Result[_T]] = self.session.execute(\n  File \"/Users/ek/dev/auth-template/venv/lib/python3.9/site-packages/sqlalchemy/orm/session.py\", line 2365, in execute\n    return self._execute_internal(\n  File \"/Users/ek/dev/auth-template/venv/lib/python3.9/site-packages/sqlalchemy/orm/session.py\", line 2239, in _execute_internal\n    bind = self.get_bind(**bind_arguments)\n  File \"/Users/ek/dev/auth-template/venv/lib/python3.9/site-packages/flask_sqlalchemy/session.py\", line 53, in get_bind\n    engines = self._db.engines\n  File \"/Users/ek/dev/auth-template/venv/lib/python3.9/site-packages/flask_sqlalchemy/extension.py\", line 690, in engines\n    raise RuntimeError(\nRuntimeError: The current Flask app is not registered with this 'SQLAlchemy' instance. Did you forget to call 'init_app', or did you create multiple 'SQLAlchemy' instances?", "error": "The current Flask app is not registered with this 'SQLAlchemy' instance. Did you forget to call 'init_app', or did you create multiple 'SQLAlchemy' instances?", "request_id": "578b9273-dd76-4c6a-8cc7-a6590029a199", "method": "POST", "path": "/api/auth/signup", "remote_addr": "127.0.0.1", "user_agent": "Werkzeug/3.1.3"}
{"timestamp": "2025-04-29T21:30:13.544269", "level": "ERROR", "name": "auth_app", "message": "Signup failed", "exc_info": "Traceback (most recent call last):\n  File \"/Users/ek/dev/auth-template/api/services/auth_service.py\", line 17, in signup\n    is_valid, error_message = ValidationService.validate_signup_input(email, password, confirm_password)\n  File \"/Users/ek/dev/auth-template/api/services/validation_service.py\", line 61, in validate_signup_input\n    existing_user = User.query.filter(User.email.ilike(email)).first()\n  File \"/Users/ek/dev/auth-template/venv/lib/python3.9/site-packages/sqlalchemy/orm/query.py\", line 2759, in first\n    return self.limit(1)._iter().first()  # type: ignore\n  File \"/Users/ek/dev/auth-template/venv/lib/python3.9/site-packages/sqlalchemy/orm/query.py\", line 2858, in _iter\n    result: Union[ScalarResult[_T], Result[_T]] = self.session.execute(\n  File \"/Users/ek/dev/auth-template/venv/lib/python3.9/site-packages/sqlalchemy/orm/session.py\", line 2365, in execute\n    return self._execute_internal(\n  File \"/Users/ek/dev/auth-template/venv/lib/python3.9/site-packages/sqlalchemy/orm/session.py\", line 2239, in _execute_internal\n    bind = self.get_bind(**bind_arguments)\n  File \"/Users/ek/dev/auth-template/venv/lib/python3.9/site-packages/flask_sqlalchemy/session.py\", line 53, in get_bind\n    engines = self._db.engines\n  File \"/Users/ek/dev/auth-template/venv/lib/python3.9/site-packages/flask_sqlalchemy/extension.py\", line 690, in engines\n    raise RuntimeError(\nRuntimeError: The current Flask app is not registered with this 'SQLAlchemy' instance. Did you forget to call 'init_app', or did you create multiple 'SQLAlchemy' instances?", "error": "The current Flask app is not registered with this 'SQLAlchemy' instance. Did you forget to call 'init_app', or did you create multiple 'SQLAlchemy' instances?", "request_id": "3f9a0c32-5b6c-4ac9-a7da-b9da7cc9911d", "method": "POST", "path": "/api/auth/signup", "remote_addr": "127.0.0.1", "user_agent": "Werkzeug/3.1.3"}
{"timestamp": "2025-04-29T21:40:29.522003", "level": "ERROR", "name": "auth_app", "message": "Signup failed", "exc_info": "Traceback (most recent call last):\n  File \"/Users/ek/dev/auth-template/api/services/auth_service.py\", line 17, in signup\n    is_valid, error_message = ValidationService.validate_signup_input(email, password, confirm_password)\n  File \"/Users/ek/dev/auth-template/api/services/validation_service.py\", line 61, in validate_signup_input\n    existing_user = User.query.filter(User.email.ilike(email)).first()\n  File \"/Users/ek/dev/auth-template/venv/lib/python3.9/site-packages/sqlalchemy/orm/query.py\", line 2759, in first\n    return self.limit(1)._iter().first()  # type: ignore\n  File \"/Users/ek/dev/auth-template/venv/lib/python3.9/site-packages/sqlalchemy/orm/query.py\", line 2858, in _iter\n    result: Union[ScalarResult[_T], Result[_T]] = self.session.execute(\n  File \"/Users/ek/dev/auth-template/venv/lib/python3.9/site-packages/sqlalchemy/orm/session.py\", line 2365, in execute\n    return self._execute_internal(\n  File \"/Users/ek/dev/auth-template/venv/lib/python3.9/site-packages/sqlalchemy/orm/session.py\", line 2239, in _execute_internal\n    bind = self.get_bind(**bind_arguments)\n  File \"/Users/ek/dev/auth-template/venv/lib/python3.9/site-packages/flask_sqlalchemy/session.py\", line 53, in get_bind\n    engines = self._db.engines\n  File \"/Users/ek/dev/auth-template/venv/lib/python3.9/site-packages/flask_sqlalchemy/extension.py\", line 690, in engines\n    raise RuntimeError(\nRuntimeError: The current Flask app is not registered with this 'SQLAlchemy' instance. Did you forget to call 'init_app', or did you create multiple 'SQLAlchemy' instances?", "error": "The current Flask app is not registered with this 'SQLAlchemy' instance. Did you forget to call 'init_app', or did you create multiple 'SQLAlchemy' instances?", "request_id": "e058bfb7-7acb-4151-b4af-4990ce214213", "method": "POST", "path": "/api/auth/signup", "remote_addr": "127.0.0.1", "user_agent": "Werkzeug/3.1.3"}
{"timestamp": "2025-04-29T21:40:29.531510", "level": "ERROR", "name": "auth_app", "message": "Login failed", "exc_info": "Traceback (most recent call last):\n  File \"/Users/ek/dev/auth-template/api/services/auth_service.py\", line 51, in login\n    user = User.query.filter(User.email.ilike(email)).first()\n  File \"/Users/ek/dev/auth-template/venv/lib/python3.9/site-packages/sqlalchemy/orm/query.py\", line 2759, in first\n    return self.limit(1)._iter().first()  # type: ignore\n  File \"/Users/ek/dev/auth-template/venv/lib/python3.9/site-packages/sqlalchemy/orm/query.py\", line 2858, in _iter\n    result: Union[ScalarResult[_T], Result[_T]] = self.session.execute(\n  File \"/Users/ek/dev/auth-template/venv/lib/python3.9/site-packages/sqlalchemy/orm/session.py\", line 2365, in execute\n    return self._execute_internal(\n  File \"/Users/ek/dev/auth-template/venv/lib/python3.9/site-packages/sqlalchemy/orm/session.py\", line 2239, in _execute_internal\n    bind = self.get_bind(**bind_arguments)\n  File \"/Users/ek/dev/auth-template/venv/lib/python3.9/site-packages/flask_sqlalchemy/session.py\", line 53, in get_bind\n    engines = self._db.engines\n  File \"/Users/ek/dev/auth-template/venv/lib/python3.9/site-packages/flask_sqlalchemy/extension.py\", line 690, in engines\n    raise RuntimeError(\nRuntimeError: The current Flask app is not registered with this 'SQLAlchemy' instance. Did you forget to call 'init_app', or did you create multiple 'SQLAlchemy' instances?", "error": "The current Flask app is not registered with this 'SQLAlchemy' instance. Did you forget to call 'init_app', or did you create multiple 'SQLAlchemy' instances?", "request_id": "64814276-ddb8-4ebb-9fc8-d0b14d58db7f", "method": "POST", "path": "/api/auth/login", "remote_addr": "127.0.0.1", "user_agent": "Werkzeug/3.1.3"}
{"timestamp": "2025-04-29T21:40:29.724360", "level": "ERROR", "name": "auth_app", "message": "Signup failed", "exc_info": "Traceback (most recent call last):\n  File \"/Users/ek/dev/auth-template/api/services/auth_service.py\", line 17, in signup\n    is_valid, error_message = ValidationService.validate_signup_input(email, password, confirm_password)\n  File \"/Users/ek/dev/auth-template/api/services/validation_service.py\", line 61, in validate_signup_input\n    existing_user = User.query.filter(User.email.ilike(email)).first()\n  File \"/Users/ek/dev/auth-template/venv/lib/python3.9/site-packages/sqlalchemy/orm/query.py\", line 2759, in first\n    return self.limit(1)._iter().first()  # type: ignore\n  File \"/Users/ek/dev/auth-template/venv/lib/python3.9/site-packages/sqlalchemy/orm/query.py\", line 2858, in _iter\n    result: Union[ScalarResult[_T], Result[_T]] = self.session.execute(\n  File \"/Users/ek/dev/auth-template/venv/lib/python3.9/site-packages/sqlalchemy/orm/session.py\", line 2365, in execute\n    return self._execute_internal(\n  File \"/Users/ek/dev/auth-template/venv/lib/python3.9/site-packages/sqlalchemy/orm/session.py\", line 2239, in _execute_internal\n    bind = self.get_bind(**bind_arguments)\n  File \"/Users/ek/dev/auth-template/venv/lib/python3.9/site-packages/flask_sqlalchemy/session.py\", line 53, in get_bind\n    engines = self._db.engines\n  File \"/Users/ek/dev/auth-template/venv/lib/python3.9/site-packages/flask_sqlalchemy/extension.py\", line 690, in engines\n    raise RuntimeError(\nRuntimeError: The current Flask app is not registered with this 'SQLAlchemy' instance. Did you forget to call 'init_app', or did you create multiple 'SQLAlchemy' instances?", "error": "The current Flask app is not registered with this 'SQLAlchemy' instance. Did you forget to call 'init_app', or did you create multiple 'SQLAlchemy' instances?", "request_id": "a114a780-d09d-40f1-a327-9b6ee8692608", "method": "POST", "path": "/api/auth/signup", "remote_addr": "127.0.0.1", "user_agent": "Werkzeug/3.1.3"}
{"timestamp": "2025-04-29T21:40:29.731789", "level": "ERROR", "name": "auth_app", "message": "Login failed", "exc_info": "Traceback (most recent call last):\n  File \"/Users/ek/dev/auth-template/api/services/auth_service.py\", line 51, in login\n    user = User.query.filter(User.email.ilike(email)).first()\n  File \"/Users/ek/dev/auth-template/venv/lib/python3.9/site-packages/sqlalchemy/orm/query.py\", line 2759, in first\n    return self.limit(1)._iter().first()  # type: ignore\n  File \"/Users/ek/dev/auth-template/venv/lib/python3.9/site-packages/sqlalchemy/orm/query.py\", line 2858, in _iter\n    result: Union[ScalarResult[_T], Result[_T]] = self.session.execute(\n  File \"/Users/ek/dev/auth-template/venv/lib/python3.9/site-packages/sqlalchemy/orm/session.py\", line 2365, in execute\n    return self._execute_internal(\n  File \"/Users/ek/dev/auth-template/venv/lib/python3.9/site-packages/sqlalchemy/orm/session.py\", line 2239, in _execute_internal\n    bind = self.get_bind(**bind_arguments)\n  File \"/Users/ek/dev/auth-template/venv/lib/python3.9/site-packages/flask_sqlalchemy/session.py\", line 53, in get_bind\n    engines = self._db.engines\n  File \"/Users/ek/dev/auth-template/venv/lib/python3.9/site-packages/flask_sqlalchemy/extension.py\", line 690, in engines\n    raise RuntimeError(\nRuntimeError: The current Flask app is not registered with this 'SQLAlchemy' instance. Did you forget to call 'init_app', or did you create multiple 'SQLAlchemy' instances?", "error": "The current Flask app is not registered with this 'SQLAlchemy' instance. Did you forget to call 'init_app', or did you create multiple 'SQLAlchemy' instances?", "request_id": "0de25a6f-6b34-42a3-bc6f-a65e20ab5b46", "method": "POST", "path": "/api/auth/login", "remote_addr": "127.0.0.1", "user_agent": "Werkzeug/3.1.3"}
{"timestamp": "2025-04-29T21:40:29.759579", "level": "ERROR", "name": "auth_app", "message": "Login failed", "exc_info": "Traceback (most recent call last):\n  File \"/Users/ek/dev/auth-template/api/services/auth_service.py\", line 51, in login\n    user = User.query.filter(User.email.ilike(email)).first()\n  File \"/Users/ek/dev/auth-template/venv/lib/python3.9/site-packages/sqlalchemy/orm/query.py\", line 2759, in first\n    return self.limit(1)._iter().first()  # type: ignore\n  File \"/Users/ek/dev/auth-template/venv/lib/python3.9/site-packages/sqlalchemy/orm/query.py\", line 2858, in _iter\n    result: Union[ScalarResult[_T], Result[_T]] = self.session.execute(\n  File \"/Users/ek/dev/auth-template/venv/lib/python3.9/site-packages/sqlalchemy/orm/session.py\", line 2365, in execute\n    return self._execute_internal(\n  File \"/Users/ek/dev/auth-template/venv/lib/python3.9/site-packages/sqlalchemy/orm/session.py\", line 2239, in _execute_internal\n    bind = self.get_bind(**bind_arguments)\n  File \"/Users/ek/dev/auth-template/venv/lib/python3.9/site-packages/flask_sqlalchemy/session.py\", line 53, in get_bind\n    engines = self._db.engines\n  File \"/Users/ek/dev/auth-template/venv/lib/python3.9/site-packages/flask_sqlalchemy/extension.py\", line 690, in engines\n    raise RuntimeError(\nRuntimeError: The current Flask app is not registered with this 'SQLAlchemy' instance. Did you forget to call 'init_app', or did you create multiple 'SQLAlchemy' instances?", "error": "The current Flask app is not registered with this 'SQLAlchemy' instance. Did you forget to call 'init_app', or did you create multiple 'SQLAlchemy' instances?", "request_id": "8494a4ee-610a-44d8-b6a5-abd40a9bc3db", "method": "POST", "path": "/api/auth/login", "remote_addr": "127.0.0.1", "user_agent": "Werkzeug/3.1.3"}
{"timestamp": "2025-04-29T21:40:29.791138", "level": "ERROR", "name": "auth_app", "message": "Signup failed", "exc_info": "Traceback (most recent call last):\n  File \"/Users/ek/dev/auth-template/api/services/auth_service.py\", line 17, in signup\n    is_valid, error_message = ValidationService.validate_signup_input(email, password, confirm_password)\n  File \"/Users/ek/dev/auth-template/api/services/validation_service.py\", line 61, in validate_signup_input\n    existing_user = User.query.filter(User.email.ilike(email)).first()\n  File \"/Users/ek/dev/auth-template/venv/lib/python3.9/site-packages/sqlalchemy/orm/query.py\", line 2759, in first\n    return self.limit(1)._iter().first()  # type: ignore\n  File \"/Users/ek/dev/auth-template/venv/lib/python3.9/site-packages/sqlalchemy/orm/query.py\", line 2858, in _iter\n    result: Union[ScalarResult[_T], Result[_T]] = self.session.execute(\n  File \"/Users/ek/dev/auth-template/venv/lib/python3.9/site-packages/sqlalchemy/orm/session.py\", line 2365, in execute\n    return self._execute_internal(\n  File \"/Users/ek/dev/auth-template/venv/lib/python3.9/site-packages/sqlalchemy/orm/session.py\", line 2239, in _execute_internal\n    bind = self.get_bind(**bind_arguments)\n  File \"/Users/ek/dev/auth-template/venv/lib/python3.9/site-packages/flask_sqlalchemy/session.py\", line 53, in get_bind\n    engines = self._db.engines\n  File \"/Users/ek/dev/auth-template/venv/lib/python3.9/site-packages/flask_sqlalchemy/extension.py\", line 690, in engines\n    raise RuntimeError(\nRuntimeError: The current Flask app is not registered with this 'SQLAlchemy' instance. Did you forget to call 'init_app', or did you create multiple 'SQLAlchemy' instances?", "error": "The current Flask app is not registered with this 'SQLAlchemy' instance. Did you forget to call 'init_app', or did you create multiple 'SQLAlchemy' instances?", "request_id": "5ce71092-da8f-445d-a085-927d4e04fbb6", "method": "POST", "path": "/api/auth/signup", "remote_addr": "127.0.0.1", "user_agent": "Werkzeug/3.1.3"}
{"timestamp": "2025-04-29T21:40:29.799330", "level": "ERROR", "name": "auth_app", "message": "Login failed", "exc_info": "Traceback (most recent call last):\n  File \"/Users/ek/dev/auth-template/api/services/auth_service.py\", line 51, in login\n    user = User.query.filter(User.email.ilike(email)).first()\n  File \"/Users/ek/dev/auth-template/venv/lib/python3.9/site-packages/sqlalchemy/orm/query.py\", line 2759, in first\n    return self.limit(1)._iter().first()  # type: ignore\n  File \"/Users/ek/dev/auth-template/venv/lib/python3.9/site-packages/sqlalchemy/orm/query.py\", line 2858, in _iter\n    result: Union[ScalarResult[_T], Result[_T]] = self.session.execute(\n  File \"/Users/ek/dev/auth-template/venv/lib/python3.9/site-packages/sqlalchemy/orm/session.py\", line 2365, in execute\n    return self._execute_internal(\n  File \"/Users/ek/dev/auth-template/venv/lib/python3.9/site-packages/sqlalchemy/orm/session.py\", line 2239, in _execute_internal\n    bind = self.get_bind(**bind_arguments)\n  File \"/Users/ek/dev/auth-template/venv/lib/python3.9/site-packages/flask_sqlalchemy/session.py\", line 53, in get_bind\n    engines = self._db.engines\n  File \"/Users/ek/dev/auth-template/venv/lib/python3.9/site-packages/flask_sqlalchemy/extension.py\", line 690, in engines\n    raise RuntimeError(\nRuntimeError: The current Flask app is not registered with this 'SQLAlchemy' instance. Did you forget to call 'init_app', or did you create multiple 'SQLAlchemy' instances?", "error": "The current Flask app is not registered with this 'SQLAlchemy' instance. Did you forget to call 'init_app', or did you create multiple 'SQLAlchemy' instances?", "request_id": "957e99f7-9005-43c2-909c-9776a5bb39de", "method": "POST", "path": "/api/auth/login", "remote_addr": "127.0.0.1", "user_agent": "Werkzeug/3.1.3"}
{"timestamp": "2025-04-29T21:40:29.844586", "level": "ERROR", "name": "auth_app", "message": "Signup failed", "exc_info": "Traceback (most recent call last):\n  File \"/Users/ek/dev/auth-template/api/services/auth_service.py\", line 17, in signup\n    is_valid, error_message = ValidationService.validate_signup_input(email, password, confirm_password)\n  File \"/Users/ek/dev/auth-template/api/services/validation_service.py\", line 61, in validate_signup_input\n    existing_user = User.query.filter(User.email.ilike(email)).first()\n  File \"/Users/ek/dev/auth-template/venv/lib/python3.9/site-packages/sqlalchemy/orm/query.py\", line 2759, in first\n    return self.limit(1)._iter().first()  # type: ignore\n  File \"/Users/ek/dev/auth-template/venv/lib/python3.9/site-packages/sqlalchemy/orm/query.py\", line 2858, in _iter\n    result: Union[ScalarResult[_T], Result[_T]] = self.session.execute(\n  File \"/Users/ek/dev/auth-template/venv/lib/python3.9/site-packages/sqlalchemy/orm/session.py\", line 2365, in execute\n    return self._execute_internal(\n  File \"/Users/ek/dev/auth-template/venv/lib/python3.9/site-packages/sqlalchemy/orm/session.py\", line 2239, in _execute_internal\n    bind = self.get_bind(**bind_arguments)\n  File \"/Users/ek/dev/auth-template/venv/lib/python3.9/site-packages/flask_sqlalchemy/session.py\", line 53, in get_bind\n    engines = self._db.engines\n  File \"/Users/ek/dev/auth-template/venv/lib/python3.9/site-packages/flask_sqlalchemy/extension.py\", line 690, in engines\n    raise RuntimeError(\nRuntimeError: The current Flask app is not registered with this 'SQLAlchemy' instance. Did you forget to call 'init_app', or did you create multiple 'SQLAlchemy' instances?", "error": "The current Flask app is not registered with this 'SQLAlchemy' instance. Did you forget to call 'init_app', or did you create multiple 'SQLAlchemy' instances?", "request_id": "af25996f-09fa-4001-bacd-e37a3ddc6849", "method": "POST", "path": "/api/auth/signup", "remote_addr": "127.0.0.1", "user_agent": "Werkzeug/3.1.3"}
{"timestamp": "2025-04-29T21:40:29.853200", "level": "ERROR", "name": "auth_app", "message": "Login failed", "exc_info": "Traceback (most recent call last):\n  File \"/Users/ek/dev/auth-template/api/services/auth_service.py\", line 51, in login\n    user = User.query.filter(User.email.ilike(email)).first()\n  File \"/Users/ek/dev/auth-template/venv/lib/python3.9/site-packages/sqlalchemy/orm/query.py\", line 2759, in first\n    return self.limit(1)._iter().first()  # type: ignore\n  File \"/Users/ek/dev/auth-template/venv/lib/python3.9/site-packages/sqlalchemy/orm/query.py\", line 2858, in _iter\n    result: Union[ScalarResult[_T], Result[_T]] = self.session.execute(\n  File \"/Users/ek/dev/auth-template/venv/lib/python3.9/site-packages/sqlalchemy/orm/session.py\", line 2365, in execute\n    return self._execute_internal(\n  File \"/Users/ek/dev/auth-template/venv/lib/python3.9/site-packages/sqlalchemy/orm/session.py\", line 2239, in _execute_internal\n    bind = self.get_bind(**bind_arguments)\n  File \"/Users/ek/dev/auth-template/venv/lib/python3.9/site-packages/flask_sqlalchemy/session.py\", line 53, in get_bind\n    engines = self._db.engines\n  File \"/Users/ek/dev/auth-template/venv/lib/python3.9/site-packages/flask_sqlalchemy/extension.py\", line 690, in engines\n    raise RuntimeError(\nRuntimeError: The current Flask app is not registered with this 'SQLAlchemy' instance. Did you forget to call 'init_app', or did you create multiple 'SQLAlchemy' instances?", "error": "The current Flask app is not registered with this 'SQLAlchemy' instance. Did you forget to call 'init_app', or did you create multiple 'SQLAlchemy' instances?", "request_id": "2c1dea60-a5f7-4582-a00a-3f3171540034", "method": "POST", "path": "/api/auth/login", "remote_addr": "127.0.0.1", "user_agent": "Werkzeug/3.1.3"}
{"timestamp": "2025-04-29T21:40:29.859968", "level": "ERROR", "name": "auth_app", "message": "Login failed", "exc_info": "Traceback (most recent call last):\n  File \"/Users/ek/dev/auth-template/api/services/auth_service.py\", line 51, in login\n    user = User.query.filter(User.email.ilike(email)).first()\n  File \"/Users/ek/dev/auth-template/venv/lib/python3.9/site-packages/sqlalchemy/orm/query.py\", line 2759, in first\n    return self.limit(1)._iter().first()  # type: ignore\n  File \"/Users/ek/dev/auth-template/venv/lib/python3.9/site-packages/sqlalchemy/orm/query.py\", line 2858, in _iter\n    result: Union[ScalarResult[_T], Result[_T]] = self.session.execute(\n  File \"/Users/ek/dev/auth-template/venv/lib/python3.9/site-packages/sqlalchemy/orm/session.py\", line 2365, in execute\n    return self._execute_internal(\n  File \"/Users/ek/dev/auth-template/venv/lib/python3.9/site-packages/sqlalchemy/orm/session.py\", line 2239, in _execute_internal\n    bind = self.get_bind(**bind_arguments)\n  File \"/Users/ek/dev/auth-template/venv/lib/python3.9/site-packages/flask_sqlalchemy/session.py\", line 53, in get_bind\n    engines = self._db.engines\n  File \"/Users/ek/dev/auth-template/venv/lib/python3.9/site-packages/flask_sqlalchemy/extension.py\", line 690, in engines\n    raise RuntimeError(\nRuntimeError: The current Flask app is not registered with this 'SQLAlchemy' instance. Did you forget to call 'init_app', or did you create multiple 'SQLAlchemy' instances?", "error": "The current Flask app is not registered with this 'SQLAlchemy' instance. Did you forget to call 'init_app', or did you create multiple 'SQLAlchemy' instances?", "request_id": "7f897e96-f572-4d6c-a63b-af5c106605bc", "method": "POST", "path": "/api/auth/login", "remote_addr": "127.0.0.1", "user_agent": "Werkzeug/3.1.3"}
{"timestamp": "2025-04-29T21:40:29.871013", "level": "ERROR", "name": "auth_app", "message": "Login failed", "exc_info": "Traceback (most recent call last):\n  File \"/Users/ek/dev/auth-template/api/services/auth_service.py\", line 51, in login\n    user = User.query.filter(User.email.ilike(email)).first()\n  File \"/Users/ek/dev/auth-template/venv/lib/python3.9/site-packages/sqlalchemy/orm/query.py\", line 2759, in first\n    return self.limit(1)._iter().first()  # type: ignore\n  File \"/Users/ek/dev/auth-template/venv/lib/python3.9/site-packages/sqlalchemy/orm/query.py\", line 2858, in _iter\n    result: Union[ScalarResult[_T], Result[_T]] = self.session.execute(\n  File \"/Users/ek/dev/auth-template/venv/lib/python3.9/site-packages/sqlalchemy/orm/session.py\", line 2365, in execute\n    return self._execute_internal(\n  File \"/Users/ek/dev/auth-template/venv/lib/python3.9/site-packages/sqlalchemy/orm/session.py\", line 2239, in _execute_internal\n    bind = self.get_bind(**bind_arguments)\n  File \"/Users/ek/dev/auth-template/venv/lib/python3.9/site-packages/flask_sqlalchemy/session.py\", line 53, in get_bind\n    engines = self._db.engines\n  File \"/Users/ek/dev/auth-template/venv/lib/python3.9/site-packages/flask_sqlalchemy/extension.py\", line 690, in engines\n    raise RuntimeError(\nRuntimeError: The current Flask app is not registered with this 'SQLAlchemy' instance. Did you forget to call 'init_app', or did you create multiple 'SQLAlchemy' instances?", "error": "The current Flask app is not registered with this 'SQLAlchemy' instance. Did you forget to call 'init_app', or did you create multiple 'SQLAlchemy' instances?", "request_id": "58bfc878-0b5d-478c-a8fc-d9fc1dda3e9f", "method": "POST", "path": "/api/auth/login", "remote_addr": "127.0.0.1", "user_agent": "Werkzeug/3.1.3"}
{"timestamp": "2025-04-29T21:40:29.879251", "level": "ERROR", "name": "auth_app", "message": "Login failed", "exc_info": "Traceback (most recent call last):\n  File \"/Users/ek/dev/auth-template/api/services/auth_service.py\", line 51, in login\n    user = User.query.filter(User.email.ilike(email)).first()\n  File \"/Users/ek/dev/auth-template/venv/lib/python3.9/site-packages/sqlalchemy/orm/query.py\", line 2759, in first\n    return self.limit(1)._iter().first()  # type: ignore\n  File \"/Users/ek/dev/auth-template/venv/lib/python3.9/site-packages/sqlalchemy/orm/query.py\", line 2858, in _iter\n    result: Union[ScalarResult[_T], Result[_T]] = self.session.execute(\n  File \"/Users/ek/dev/auth-template/venv/lib/python3.9/site-packages/sqlalchemy/orm/session.py\", line 2365, in execute\n    return self._execute_internal(\n  File \"/Users/ek/dev/auth-template/venv/lib/python3.9/site-packages/sqlalchemy/orm/session.py\", line 2239, in _execute_internal\n    bind = self.get_bind(**bind_arguments)\n  File \"/Users/ek/dev/auth-template/venv/lib/python3.9/site-packages/flask_sqlalchemy/session.py\", line 53, in get_bind\n    engines = self._db.engines\n  File \"/Users/ek/dev/auth-template/venv/lib/python3.9/site-packages/flask_sqlalchemy/extension.py\", line 690, in engines\n    raise RuntimeError(\nRuntimeError: The current Flask app is not registered with this 'SQLAlchemy' instance. Did you forget to call 'init_app', or did you create multiple 'SQLAlchemy' instances?", "error": "The current Flask app is not registered with this 'SQLAlchemy' instance. Did you forget to call 'init_app', or did you create multiple 'SQLAlchemy' instances?", "request_id": "27f9cd4f-1556-47fa-a54d-ec1a58b48c93", "method": "POST", "path": "/api/auth/login", "remote_addr": "127.0.0.1", "user_agent": "Werkzeug/3.1.3"}
{"timestamp": "2025-04-29T21:40:29.886369", "level": "ERROR", "name": "auth_app", "message": "Login failed", "exc_info": "Traceback (most recent call last):\n  File \"/Users/ek/dev/auth-template/api/services/auth_service.py\", line 51, in login\n    user = User.query.filter(User.email.ilike(email)).first()\n  File \"/Users/ek/dev/auth-template/venv/lib/python3.9/site-packages/sqlalchemy/orm/query.py\", line 2759, in first\n    return self.limit(1)._iter().first()  # type: ignore\n  File \"/Users/ek/dev/auth-template/venv/lib/python3.9/site-packages/sqlalchemy/orm/query.py\", line 2858, in _iter\n    result: Union[ScalarResult[_T], Result[_T]] = self.session.execute(\n  File \"/Users/ek/dev/auth-template/venv/lib/python3.9/site-packages/sqlalchemy/orm/session.py\", line 2365, in execute\n    return self._execute_internal(\n  File \"/Users/ek/dev/auth-template/venv/lib/python3.9/site-packages/sqlalchemy/orm/session.py\", line 2239, in _execute_internal\n    bind = self.get_bind(**bind_arguments)\n  File \"/Users/ek/dev/auth-template/venv/lib/python3.9/site-packages/flask_sqlalchemy/session.py\", line 53, in get_bind\n    engines = self._db.engines\n  File \"/Users/ek/dev/auth-template/venv/lib/python3.9/site-packages/flask_sqlalchemy/extension.py\", line 690, in engines\n    raise RuntimeError(\nRuntimeError: The current Flask app is not registered with this 'SQLAlchemy' instance. Did you forget to call 'init_app', or did you create multiple 'SQLAlchemy' instances?", "error": "The current Flask app is not registered with this 'SQLAlchemy' instance. Did you forget to call 'init_app', or did you create multiple 'SQLAlchemy' instances?", "request_id": "107de9d2-f410-4400-90e1-2de2b2795280", "method": "POST", "path": "/api/auth/login", "remote_addr": "127.0.0.1", "user_agent": "Werkzeug/3.1.3"}
{"timestamp": "2025-04-29T21:40:29.894597", "level": "ERROR", "name": "auth_app", "message": "Login failed", "exc_info": "Traceback (most recent call last):\n  File \"/Users/ek/dev/auth-template/api/services/auth_service.py\", line 51, in login\n    user = User.query.filter(User.email.ilike(email)).first()\n  File \"/Users/ek/dev/auth-template/venv/lib/python3.9/site-packages/sqlalchemy/orm/query.py\", line 2759, in first\n    return self.limit(1)._iter().first()  # type: ignore\n  File \"/Users/ek/dev/auth-template/venv/lib/python3.9/site-packages/sqlalchemy/orm/query.py\", line 2858, in _iter\n    result: Union[ScalarResult[_T], Result[_T]] = self.session.execute(\n  File \"/Users/ek/dev/auth-template/venv/lib/python3.9/site-packages/sqlalchemy/orm/session.py\", line 2365, in execute\n    return self._execute_internal(\n  File \"/Users/ek/dev/auth-template/venv/lib/python3.9/site-packages/sqlalchemy/orm/session.py\", line 2239, in _execute_internal\n    bind = self.get_bind(**bind_arguments)\n  File \"/Users/ek/dev/auth-template/venv/lib/python3.9/site-packages/flask_sqlalchemy/session.py\", line 53, in get_bind\n    engines = self._db.engines\n  File \"/Users/ek/dev/auth-template/venv/lib/python3.9/site-packages/flask_sqlalchemy/extension.py\", line 690, in engines\n    raise RuntimeError(\nRuntimeError: The current Flask app is not registered with this 'SQLAlchemy' instance. Did you forget to call 'init_app', or did you create multiple 'SQLAlchemy' instances?", "error": "The current Flask app is not registered with this 'SQLAlchemy' instance. Did you forget to call 'init_app', or did you create multiple 'SQLAlchemy' instances?", "request_id": "0323042b-2c79-447b-b54c-92c5558e95f9", "method": "POST", "path": "/api/auth/login", "remote_addr": "127.0.0.1", "user_agent": "Werkzeug/3.1.3"}
{"timestamp": "2025-04-29T21:40:29.920138", "level": "ERROR", "name": "auth_app", "message": "Signup failed", "exc_info": "Traceback (most recent call last):\n  File \"/Users/ek/dev/auth-template/api/services/auth_service.py\", line 17, in signup\n    is_valid, error_message = ValidationService.validate_signup_input(email, password, confirm_password)\n  File \"/Users/ek/dev/auth-template/api/services/validation_service.py\", line 61, in validate_signup_input\n    existing_user = User.query.filter(User.email.ilike(email)).first()\n  File \"/Users/ek/dev/auth-template/venv/lib/python3.9/site-packages/sqlalchemy/orm/query.py\", line 2759, in first\n    return self.limit(1)._iter().first()  # type: ignore\n  File \"/Users/ek/dev/auth-template/venv/lib/python3.9/site-packages/sqlalchemy/orm/query.py\", line 2858, in _iter\n    result: Union[ScalarResult[_T], Result[_T]] = self.session.execute(\n  File \"/Users/ek/dev/auth-template/venv/lib/python3.9/site-packages/sqlalchemy/orm/session.py\", line 2365, in execute\n    return self._execute_internal(\n  File \"/Users/ek/dev/auth-template/venv/lib/python3.9/site-packages/sqlalchemy/orm/session.py\", line 2239, in _execute_internal\n    bind = self.get_bind(**bind_arguments)\n  File \"/Users/ek/dev/auth-template/venv/lib/python3.9/site-packages/flask_sqlalchemy/session.py\", line 53, in get_bind\n    engines = self._db.engines\n  File \"/Users/ek/dev/auth-template/venv/lib/python3.9/site-packages/flask_sqlalchemy/extension.py\", line 690, in engines\n    raise RuntimeError(\nRuntimeError: The current Flask app is not registered with this 'SQLAlchemy' instance. Did you forget to call 'init_app', or did you create multiple 'SQLAlchemy' instances?", "error": "The current Flask app is not registered with this 'SQLAlchemy' instance. Did you forget to call 'init_app', or did you create multiple 'SQLAlchemy' instances?", "request_id": "dd59daee-fb03-4188-828c-a9e4826a25be", "method": "POST", "path": "/api/auth/signup", "remote_addr": "127.0.0.1", "user_agent": "Werkzeug/3.1.3"}
{"timestamp": "2025-04-29T21:40:30.001652", "level": "ERROR", "name": "auth_app", "message": "Signup failed", "exc_info": "Traceback (most recent call last):\n  File \"/Users/ek/dev/auth-template/api/services/auth_service.py\", line 17, in signup\n    is_valid, error_message = ValidationService.validate_signup_input(email, password, confirm_password)\n  File \"/Users/ek/dev/auth-template/api/services/validation_service.py\", line 61, in validate_signup_input\n    existing_user = User.query.filter(User.email.ilike(email)).first()\n  File \"/Users/ek/dev/auth-template/venv/lib/python3.9/site-packages/sqlalchemy/orm/query.py\", line 2759, in first\n    return self.limit(1)._iter().first()  # type: ignore\n  File \"/Users/ek/dev/auth-template/venv/lib/python3.9/site-packages/sqlalchemy/orm/query.py\", line 2858, in _iter\n    result: Union[ScalarResult[_T], Result[_T]] = self.session.execute(\n  File \"/Users/ek/dev/auth-template/venv/lib/python3.9/site-packages/sqlalchemy/orm/session.py\", line 2365, in execute\n    return self._execute_internal(\n  File \"/Users/ek/dev/auth-template/venv/lib/python3.9/site-packages/sqlalchemy/orm/session.py\", line 2239, in _execute_internal\n    bind = self.get_bind(**bind_arguments)\n  File \"/Users/ek/dev/auth-template/venv/lib/python3.9/site-packages/flask_sqlalchemy/session.py\", line 53, in get_bind\n    engines = self._db.engines\n  File \"/Users/ek/dev/auth-template/venv/lib/python3.9/site-packages/flask_sqlalchemy/extension.py\", line 690, in engines\n    raise RuntimeError(\nRuntimeError: The current Flask app is not registered with this 'SQLAlchemy' instance. Did you forget to call 'init_app', or did you create multiple 'SQLAlchemy' instances?", "error": "The current Flask app is not registered with this 'SQLAlchemy' instance. Did you forget to call 'init_app', or did you create multiple 'SQLAlchemy' instances?", "request_id": "272b8902-dbf3-4b9f-bfdc-576acd542228", "method": "POST", "path": "/api/auth/signup", "remote_addr": "127.0.0.1", "user_agent": "Werkzeug/3.1.3"}
{"timestamp": "2025-04-29T21:40:30.033491", "level": "ERROR", "name": "auth_app", "message": "Signup failed", "exc_info": "Traceback (most recent call last):\n  File \"/Users/ek/dev/auth-template/api/services/auth_service.py\", line 17, in signup\n    is_valid, error_message = ValidationService.validate_signup_input(email, password, confirm_password)\n  File \"/Users/ek/dev/auth-template/api/services/validation_service.py\", line 61, in validate_signup_input\n    existing_user = User.query.filter(User.email.ilike(email)).first()\n  File \"/Users/ek/dev/auth-template/venv/lib/python3.9/site-packages/sqlalchemy/orm/query.py\", line 2759, in first\n    return self.limit(1)._iter().first()  # type: ignore\n  File \"/Users/ek/dev/auth-template/venv/lib/python3.9/site-packages/sqlalchemy/orm/query.py\", line 2858, in _iter\n    result: Union[ScalarResult[_T], Result[_T]] = self.session.execute(\n  File \"/Users/ek/dev/auth-template/venv/lib/python3.9/site-packages/sqlalchemy/orm/session.py\", line 2365, in execute\n    return self._execute_internal(\n  File \"/Users/ek/dev/auth-template/venv/lib/python3.9/site-packages/sqlalchemy/orm/session.py\", line 2239, in _execute_internal\n    bind = self.get_bind(**bind_arguments)\n  File \"/Users/ek/dev/auth-template/venv/lib/python3.9/site-packages/flask_sqlalchemy/session.py\", line 53, in get_bind\n    engines = self._db.engines\n  File \"/Users/ek/dev/auth-template/venv/lib/python3.9/site-packages/flask_sqlalchemy/extension.py\", line 690, in engines\n    raise RuntimeError(\nRuntimeError: The current Flask app is not registered with this 'SQLAlchemy' instance. Did you forget to call 'init_app', or did you create multiple 'SQLAlchemy' instances?", "error": "The current Flask app is not registered with this 'SQLAlchemy' instance. Did you forget to call 'init_app', or did you create multiple 'SQLAlchemy' instances?", "request_id": "92816a86-8a77-49dd-80bf-3a3b681907db", "method": "POST", "path": "/api/auth/signup", "remote_addr": "127.0.0.1", "user_agent": "Werkzeug/3.1.3"}
{"timestamp": "2025-04-29T21:40:30.064057", "level": "ERROR", "name": "auth_app", "message": "Signup failed", "exc_info": "Traceback (most recent call last):\n  File \"/Users/ek/dev/auth-template/api/services/auth_service.py\", line 17, in signup\n    is_valid, error_message = ValidationService.validate_signup_input(email, password, confirm_password)\n  File \"/Users/ek/dev/auth-template/api/services/validation_service.py\", line 61, in validate_signup_input\n    existing_user = User.query.filter(User.email.ilike(email)).first()\n  File \"/Users/ek/dev/auth-template/venv/lib/python3.9/site-packages/sqlalchemy/orm/query.py\", line 2759, in first\n    return self.limit(1)._iter().first()  # type: ignore\n  File \"/Users/ek/dev/auth-template/venv/lib/python3.9/site-packages/sqlalchemy/orm/query.py\", line 2858, in _iter\n    result: Union[ScalarResult[_T], Result[_T]] = self.session.execute(\n  File \"/Users/ek/dev/auth-template/venv/lib/python3.9/site-packages/sqlalchemy/orm/session.py\", line 2365, in execute\n    return self._execute_internal(\n  File \"/Users/ek/dev/auth-template/venv/lib/python3.9/site-packages/sqlalchemy/orm/session.py\", line 2239, in _execute_internal\n    bind = self.get_bind(**bind_arguments)\n  File \"/Users/ek/dev/auth-template/venv/lib/python3.9/site-packages/flask_sqlalchemy/session.py\", line 53, in get_bind\n    engines = self._db.engines\n  File \"/Users/ek/dev/auth-template/venv/lib/python3.9/site-packages/flask_sqlalchemy/extension.py\", line 690, in engines\n    raise RuntimeError(\nRuntimeError: The current Flask app is not registered with this 'SQLAlchemy' instance. Did you forget to call 'init_app', or did you create multiple 'SQLAlchemy' instances?", "error": "The current Flask app is not registered with this 'SQLAlchemy' instance. Did you forget to call 'init_app', or did you create multiple 'SQLAlchemy' instances?", "request_id": "d7faf887-45e9-4b2b-8f05-3813c7109d22", "method": "POST", "path": "/api/auth/signup", "remote_addr": "127.0.0.1", "user_agent": "Werkzeug/3.1.3"}
{"timestamp": "2025-04-29T21:40:30.070555", "level": "ERROR", "name": "auth_app", "message": "Signup failed", "exc_info": "Traceback (most recent call last):\n  File \"/Users/ek/dev/auth-template/api/services/auth_service.py\", line 17, in signup\n    is_valid, error_message = ValidationService.validate_signup_input(email, password, confirm_password)\n  File \"/Users/ek/dev/auth-template/api/services/validation_service.py\", line 61, in validate_signup_input\n    existing_user = User.query.filter(User.email.ilike(email)).first()\n  File \"/Users/ek/dev/auth-template/venv/lib/python3.9/site-packages/sqlalchemy/orm/query.py\", line 2759, in first\n    return self.limit(1)._iter().first()  # type: ignore\n  File \"/Users/ek/dev/auth-template/venv/lib/python3.9/site-packages/sqlalchemy/orm/query.py\", line 2858, in _iter\n    result: Union[ScalarResult[_T], Result[_T]] = self.session.execute(\n  File \"/Users/ek/dev/auth-template/venv/lib/python3.9/site-packages/sqlalchemy/orm/session.py\", line 2365, in execute\n    return self._execute_internal(\n  File \"/Users/ek/dev/auth-template/venv/lib/python3.9/site-packages/sqlalchemy/orm/session.py\", line 2239, in _execute_internal\n    bind = self.get_bind(**bind_arguments)\n  File \"/Users/ek/dev/auth-template/venv/lib/python3.9/site-packages/flask_sqlalchemy/session.py\", line 53, in get_bind\n    engines = self._db.engines\n  File \"/Users/ek/dev/auth-template/venv/lib/python3.9/site-packages/flask_sqlalchemy/extension.py\", line 690, in engines\n    raise RuntimeError(\nRuntimeError: The current Flask app is not registered with this 'SQLAlchemy' instance. Did you forget to call 'init_app', or did you create multiple 'SQLAlchemy' instances?", "error": "The current Flask app is not registered with this 'SQLAlchemy' instance. Did you forget to call 'init_app', or did you create multiple 'SQLAlchemy' instances?", "request_id": "af3379bd-ead9-46dd-9713-ff8fe9ce6715", "method": "POST", "path": "/api/auth/signup", "remote_addr": "127.0.0.1", "user_agent": "Werkzeug/3.1.3"}
{"timestamp": "2025-04-29T21:40:30.127045", "level": "ERROR", "name": "auth_app", "message": "Signup failed", "exc_info": "Traceback (most recent call last):\n  File \"/Users/ek/dev/auth-template/api/services/auth_service.py\", line 17, in signup\n    is_valid, error_message = ValidationService.validate_signup_input(email, password, confirm_password)\n  File \"/Users/ek/dev/auth-template/api/services/validation_service.py\", line 61, in validate_signup_input\n    existing_user = User.query.filter(User.email.ilike(email)).first()\n  File \"/Users/ek/dev/auth-template/venv/lib/python3.9/site-packages/sqlalchemy/orm/query.py\", line 2759, in first\n    return self.limit(1)._iter().first()  # type: ignore\n  File \"/Users/ek/dev/auth-template/venv/lib/python3.9/site-packages/sqlalchemy/orm/query.py\", line 2858, in _iter\n    result: Union[ScalarResult[_T], Result[_T]] = self.session.execute(\n  File \"/Users/ek/dev/auth-template/venv/lib/python3.9/site-packages/sqlalchemy/orm/session.py\", line 2365, in execute\n    return self._execute_internal(\n  File \"/Users/ek/dev/auth-template/venv/lib/python3.9/site-packages/sqlalchemy/orm/session.py\", line 2239, in _execute_internal\n    bind = self.get_bind(**bind_arguments)\n  File \"/Users/ek/dev/auth-template/venv/lib/python3.9/site-packages/flask_sqlalchemy/session.py\", line 53, in get_bind\n    engines = self._db.engines\n  File \"/Users/ek/dev/auth-template/venv/lib/python3.9/site-packages/flask_sqlalchemy/extension.py\", line 690, in engines\n    raise RuntimeError(\nRuntimeError: The current Flask app is not registered with this 'SQLAlchemy' instance. Did you forget to call 'init_app', or did you create multiple 'SQLAlchemy' instances?", "error": "The current Flask app is not registered with this 'SQLAlchemy' instance. Did you forget to call 'init_app', or did you create multiple 'SQLAlchemy' instances?", "request_id": "f5d86814-c654-465b-a589-c8f13c371593", "method": "POST", "path": "/api/auth/signup", "remote_addr": "127.0.0.1", "user_agent": "Werkzeug/3.1.3"}
{"timestamp": "2025-04-29T21:40:30.182435", "level": "ERROR", "name": "auth_app", "message": "Signup failed", "exc_info": "Traceback (most recent call last):\n  File \"/Users/ek/dev/auth-template/api/services/auth_service.py\", line 17, in signup\n    is_valid, error_message = ValidationService.validate_signup_input(email, password, confirm_password)\n  File \"/Users/ek/dev/auth-template/api/services/validation_service.py\", line 61, in validate_signup_input\n    existing_user = User.query.filter(User.email.ilike(email)).first()\n  File \"/Users/ek/dev/auth-template/venv/lib/python3.9/site-packages/sqlalchemy/orm/query.py\", line 2759, in first\n    return self.limit(1)._iter().first()  # type: ignore\n  File \"/Users/ek/dev/auth-template/venv/lib/python3.9/site-packages/sqlalchemy/orm/query.py\", line 2858, in _iter\n    result: Union[ScalarResult[_T], Result[_T]] = self.session.execute(\n  File \"/Users/ek/dev/auth-template/venv/lib/python3.9/site-packages/sqlalchemy/orm/session.py\", line 2365, in execute\n    return self._execute_internal(\n  File \"/Users/ek/dev/auth-template/venv/lib/python3.9/site-packages/sqlalchemy/orm/session.py\", line 2239, in _execute_internal\n    bind = self.get_bind(**bind_arguments)\n  File \"/Users/ek/dev/auth-template/venv/lib/python3.9/site-packages/flask_sqlalchemy/session.py\", line 53, in get_bind\n    engines = self._db.engines\n  File \"/Users/ek/dev/auth-template/venv/lib/python3.9/site-packages/flask_sqlalchemy/extension.py\", line 690, in engines\n    raise RuntimeError(\nRuntimeError: The current Flask app is not registered with this 'SQLAlchemy' instance. Did you forget to call 'init_app', or did you create multiple 'SQLAlchemy' instances?", "error": "The current Flask app is not registered with this 'SQLAlchemy' instance. Did you forget to call 'init_app', or did you create multiple 'SQLAlchemy' instances?", "request_id": "b9deb4f0-ea7e-4860-b76d-7631af72b35d", "method": "POST", "path": "/api/auth/signup", "remote_addr": "127.0.0.1", "user_agent": "Werkzeug/3.1.3"}
{"timestamp": "2025-04-29T21:46:20.089795", "level": "ERROR", "name": "auth_app", "message": "Signup failed", "exc_info": "Traceback (most recent call last):\n  File \"/Users/ek/dev/auth-template/api/services/auth_service.py\", line 23, in signup\n    new_user = User(\nTypeError: __init__() got an unexpected keyword argument 'id'", "error": "__init__() got an unexpected keyword argument 'id'", "request_id": "7064cf10-6985-46b0-82d2-e4bb072a570d", "method": "POST", "path": "/api/auth/signup", "remote_addr": "127.0.0.1", "user_agent": "Werkzeug/3.1.3"}
{"timestamp": "2025-04-29T21:46:20.769342", "level": "ERROR", "name": "auth_app", "message": "Signup failed", "exc_info": "Traceback (most recent call last):\n  File \"/Users/ek/dev/auth-template/api/services/auth_service.py\", line 23, in signup\n    new_user = User(\nTypeError: __init__() got an unexpected keyword argument 'id'", "error": "__init__() got an unexpected keyword argument 'id'", "request_id": "97364a31-131b-4f90-aa02-49f63b353836", "method": "POST", "path": "/api/auth/signup", "remote_addr": "127.0.0.1", "user_agent": "Werkzeug/3.1.3"}
{"timestamp": "2025-04-29T21:46:21.700028", "level": "ERROR", "name": "auth_app", "message": "Signup failed", "exc_info": "Traceback (most recent call last):\n  File \"/Users/ek/dev/auth-template/api/services/auth_service.py\", line 23, in signup\n    new_user = User(\nTypeError: __init__() got an unexpected keyword argument 'id'", "error": "__init__() got an unexpected keyword argument 'id'", "request_id": "cf7fc668-364f-4ffa-94d6-b7c5b08e8d4b", "method": "POST", "path": "/api/auth/signup", "remote_addr": "127.0.0.1", "user_agent": "Werkzeug/3.1.3"}
{"timestamp": "2025-04-29T21:46:22.335674", "level": "ERROR", "name": "auth_app", "message": "Signup failed", "exc_info": "Traceback (most recent call last):\n  File \"/Users/ek/dev/auth-template/api/services/auth_service.py\", line 23, in signup\n    new_user = User(\nTypeError: __init__() got an unexpected keyword argument 'id'", "error": "__init__() got an unexpected keyword argument 'id'", "request_id": "0494f684-90e7-4754-92fb-45886030ca77", "method": "POST", "path": "/api/auth/signup", "remote_addr": "127.0.0.1", "user_agent": "Werkzeug/3.1.3"}
{"timestamp": "2025-04-29T21:46:24.414866", "level": "ERROR", "name": "auth_app", "message": "Signup failed", "exc_info": "Traceback (most recent call last):\n  File \"/Users/ek/dev/auth-template/api/services/auth_service.py\", line 23, in signup\n    new_user = User(\nTypeError: __init__() got an unexpected keyword argument 'id'", "error": "__init__() got an unexpected keyword argument 'id'", "request_id": "1ab2d68a-01d7-4255-b9fc-7eeefadbfe64", "method": "POST", "path": "/api/auth/signup", "remote_addr": "127.0.0.1", "user_agent": "Werkzeug/3.1.3"}
{"timestamp": "2025-04-29T21:46:24.875042", "level": "ERROR", "name": "auth_app", "message": "Signup failed", "exc_info": "Traceback (most recent call last):\n  File \"/Users/ek/dev/auth-template/api/services/auth_service.py\", line 23, in signup\n    new_user = User(\nTypeError: __init__() got an unexpected keyword argument 'id'", "error": "__init__() got an unexpected keyword argument 'id'", "request_id": "c837c652-bd15-45ea-b3bf-b5467f5c3cc2", "method": "POST", "path": "/api/auth/signup", "remote_addr": "127.0.0.1", "user_agent": "Werkzeug/3.1.3"}
{"timestamp": "2025-04-29T21:46:25.174052", "level": "ERROR", "name": "auth_app", "message": "Signup failed", "exc_info": "Traceback (most recent call last):\n  File \"/Users/ek/dev/auth-template/api/services/auth_service.py\", line 23, in signup\n    new_user = User(\nTypeError: __init__() got an unexpected keyword argument 'id'", "error": "__init__() got an unexpected keyword argument 'id'", "request_id": "444ab098-1dad-41c0-afac-bbc0c6259053", "method": "POST", "path": "/api/auth/signup", "remote_addr": "127.0.0.1", "user_agent": "Werkzeug/3.1.3"}
{"timestamp": "2025-04-29T21:46:25.520762", "level": "ERROR", "name": "auth_app", "message": "Signup failed", "exc_info": "Traceback (most recent call last):\n  File \"/Users/ek/dev/auth-template/api/services/auth_service.py\", line 23, in signup\n    new_user = User(\nTypeError: __init__() got an unexpected keyword argument 'id'", "error": "__init__() got an unexpected keyword argument 'id'", "request_id": "a4a70c84-97c5-4348-af68-bdb9dfa18160", "method": "POST", "path": "/api/auth/signup", "remote_addr": "127.0.0.1", "user_agent": "Werkzeug/3.1.3"}
{"timestamp": "2025-04-29T21:49:52.340532", "level": "ERROR", "name": "auth_app", "message": "Error during signup: tuple indices must be integers or slices, not str", "request_id": "6964936e-d370-4d16-8c72-8f84414abfbd", "method": "POST", "path": "/api/auth/signup", "remote_addr": "127.0.0.1", "user_agent": "Werkzeug/3.1.3"}
{"timestamp": "2025-04-29T21:49:52.344093", "level": "ERROR", "name": "auth_app", "message": "Error during login: tuple indices must be integers or slices, not str", "request_id": "72714589-aa08-4702-97b0-ee712a3b9476", "method": "POST", "path": "/api/auth/login", "remote_addr": "127.0.0.1", "user_agent": "Werkzeug/3.1.3"}
{"timestamp": "2025-04-29T21:49:52.417568", "level": "ERROR", "name": "auth_app", "message": "Error during login: tuple indices must be integers or slices, not str", "request_id": "beb527c8-8977-4b97-99fe-d052a0b0bac0", "method": "POST", "path": "/api/auth/login", "remote_addr": "127.0.0.1", "user_agent": "Werkzeug/3.1.3"}
{"timestamp": "2025-04-29T21:49:52.458860", "level": "ERROR", "name": "auth_app", "message": "Error during signup: tuple indices must be integers or slices, not str", "request_id": "419613cd-4636-433f-93ef-576626fcabb0", "method": "POST", "path": "/api/auth/signup", "remote_addr": "127.0.0.1", "user_agent": "Werkzeug/3.1.3"}
{"timestamp": "2025-04-29T21:49:52.466002", "level": "ERROR", "name": "auth_app", "message": "Error during login: tuple indices must be integers or slices, not str", "request_id": "161e248c-e9f8-4c5b-ba19-5e89d7523e9e", "method": "POST", "path": "/api/auth/login", "remote_addr": "127.0.0.1", "user_agent": "Werkzeug/3.1.3"}
{"timestamp": "2025-04-29T21:49:52.506436", "level": "ERROR", "name": "auth_app", "message": "Error during login: tuple indices must be integers or slices, not str", "request_id": "e36dd2d4-bde4-4613-8227-df7bef8d576e", "method": "POST", "path": "/api/auth/login", "remote_addr": "127.0.0.1", "user_agent": "Werkzeug/3.1.3"}
{"timestamp": "2025-04-29T21:49:52.553474", "level": "ERROR", "name": "auth_app", "message": "Error during signup: tuple indices must be integers or slices, not str", "request_id": "cef09b12-a2c3-4d4a-b818-f191922231e0", "method": "POST", "path": "/api/auth/signup", "remote_addr": "127.0.0.1", "user_agent": "Werkzeug/3.1.3"}
{"timestamp": "2025-04-29T21:49:52.558204", "level": "ERROR", "name": "auth_app", "message": "Error during login: tuple indices must be integers or slices, not str", "request_id": "deec4778-e700-4a10-acb7-f961d29026b2", "method": "POST", "path": "/api/auth/login", "remote_addr": "127.0.0.1", "user_agent": "Werkzeug/3.1.3"}
{"timestamp": "2025-04-29T21:49:52.625512", "level": "ERROR", "name": "auth_app", "message": "Error during signup: tuple indices must be integers or slices, not str", "request_id": "10131eec-fe3d-423c-bc16-eaf322cbd306", "method": "POST", "path": "/api/auth/signup", "remote_addr": "127.0.0.1", "user_agent": "Werkzeug/3.1.3"}
{"timestamp": "2025-04-29T21:49:52.630630", "level": "ERROR", "name": "auth_app", "message": "Error during login: tuple indices must be integers or slices, not str", "request_id": "8dd4ed3e-aa31-41c0-821e-919ee7ea3d17", "method": "POST", "path": "/api/auth/login", "remote_addr": "127.0.0.1", "user_agent": "Werkzeug/3.1.3"}
{"timestamp": "2025-04-29T21:49:52.637311", "level": "ERROR", "name": "auth_app", "message": "Error during login: tuple indices must be integers or slices, not str", "request_id": "8123c3f9-768f-4e78-b714-ad69d6edd5e3", "method": "POST", "path": "/api/auth/login", "remote_addr": "127.0.0.1", "user_agent": "Werkzeug/3.1.3"}
{"timestamp": "2025-04-29T21:49:52.645115", "level": "ERROR", "name": "auth_app", "message": "Error during login: tuple indices must be integers or slices, not str", "request_id": "c99cbc67-e8dc-4e98-bbd4-c70ffb605246", "method": "POST", "path": "/api/auth/login", "remote_addr": "127.0.0.1", "user_agent": "Werkzeug/3.1.3"}
{"timestamp": "2025-04-29T21:49:52.651679", "level": "ERROR", "name": "auth_app", "message": "Error during login: tuple indices must be integers or slices, not str", "request_id": "5f4041f2-3b61-4979-8d55-a8d999eb93a4", "method": "POST", "path": "/api/auth/login", "remote_addr": "127.0.0.1", "user_agent": "Werkzeug/3.1.3"}
{"timestamp": "2025-04-29T21:49:52.657069", "level": "ERROR", "name": "auth_app", "message": "Error during login: tuple indices must be integers or slices, not str", "request_id": "85d1ec2c-86e8-43f6-9902-19955c190d47", "method": "POST", "path": "/api/auth/login", "remote_addr": "127.0.0.1", "user_agent": "Werkzeug/3.1.3"}
{"timestamp": "2025-04-29T21:49:52.663390", "level": "ERROR", "name": "auth_app", "message": "Error during login: tuple indices must be integers or slices, not str", "request_id": "24cf36b0-1fd3-4192-a5a3-e1bed5251143", "method": "POST", "path": "/api/auth/login", "remote_addr": "127.0.0.1", "user_agent": "Werkzeug/3.1.3"}
{"timestamp": "2025-04-29T21:49:52.702798", "level": "ERROR", "name": "auth_app", "message": "Error during signup: tuple indices must be integers or slices, not str", "request_id": "0f60e3cd-3dad-4fc7-a3c7-1df28cf24451", "method": "POST", "path": "/api/auth/signup", "remote_addr": "127.0.0.1", "user_agent": "Werkzeug/3.1.3"}
{"timestamp": "2025-04-29T21:49:52.773884", "level": "ERROR", "name": "auth_app", "message": "Error during signup: tuple indices must be integers or slices, not str", "request_id": "f8e5f8cb-9061-455c-b81b-8ad99daf3900", "method": "POST", "path": "/api/auth/signup", "remote_addr": "127.0.0.1", "user_agent": "Werkzeug/3.1.3"}
{"timestamp": "2025-04-29T21:49:52.853751", "level": "ERROR", "name": "auth_app", "message": "Error during signup: tuple indices must be integers or slices, not str", "request_id": "db81e340-3175-477c-9ccf-2bbb017a41e8", "method": "POST", "path": "/api/auth/signup", "remote_addr": "127.0.0.1", "user_agent": "Werkzeug/3.1.3"}
{"timestamp": "2025-04-29T21:49:52.897445", "level": "ERROR", "name": "auth_app", "message": "Error during signup: tuple indices must be integers or slices, not str", "request_id": "6528b8e1-94e8-4ec6-8f6a-e78343bd2ecd", "method": "POST", "path": "/api/auth/signup", "remote_addr": "127.0.0.1", "user_agent": "Werkzeug/3.1.3"}
{"timestamp": "2025-04-29T21:49:52.936393", "level": "ERROR", "name": "auth_app", "message": "Error during signup: tuple indices must be integers or slices, not str", "request_id": "6a463b8d-49ba-4e7f-a1dc-111b672b5347", "method": "POST", "path": "/api/auth/signup", "remote_addr": "127.0.0.1", "user_agent": "Werkzeug/3.1.3"}
{"timestamp": "2025-04-29T21:49:52.946382", "level": "ERROR", "name": "auth_app", "message": "Error during signup: tuple indices must be integers or slices, not str", "request_id": "acc50d28-63e2-4bd0-97ee-c660d0b0cd48", "method": "POST", "path": "/api/auth/signup", "remote_addr": "127.0.0.1", "user_agent": "Werkzeug/3.1.3"}
{"timestamp": "2025-04-29T21:49:53.074871", "level": "ERROR", "name": "auth_app", "message": "Error during signup: tuple indices must be integers or slices, not str", "request_id": "cee2227a-bf0c-4a61-9279-67f6191ecb64", "method": "POST", "path": "/api/auth/signup", "remote_addr": "127.0.0.1", "user_agent": "Werkzeug/3.1.3"}
{"timestamp": "2025-04-29T21:49:53.108843", "level": "ERROR", "name": "auth_app", "message": "Error during signup: tuple indices must be integers or slices, not str", "request_id": "06106f22-68a4-415d-97c4-a295e40b310c", "method": "POST", "path": "/api/auth/signup", "remote_addr": "127.0.0.1", "user_agent": "Werkzeug/3.1.3"}
{"timestamp": "2025-04-29T21:49:53.152285", "level": "ERROR", "name": "auth_app", "message": "Error during signup: tuple indices must be integers or slices, not str", "request_id": "87efbe3c-8f34-43d8-b17c-1b38e1accaa4", "method": "POST", "path": "/api/auth/signup", "remote_addr": "127.0.0.1", "user_agent": "Werkzeug/3.1.3"}
{"timestamp": "2025-04-29T21:49:53.190075", "level": "ERROR", "name": "auth_app", "message": "Error during signup: tuple indices must be integers or slices, not str", "request_id": "d4834bce-a9a2-4b5a-a8b3-90e7a3f7575a", "method": "POST", "path": "/api/auth/signup", "remote_addr": "127.0.0.1", "user_agent": "Werkzeug/3.1.3"}
{"timestamp": "2025-04-29T21:53:32.899630", "level": "ERROR", "name": "auth_app", "message": "Error during login: type object 'datetime.datetime' has no attribute 'datetime'", "request_id": "3f7947c6-f152-4e3b-aa79-10981e8b1c81", "method": "POST", "path": "/api/auth/login", "remote_addr": "127.0.0.1", "user_agent": "Werkzeug/3.1.3"}
{"timestamp": "2025-04-29T21:53:34.244822", "level": "ERROR", "name": "auth_app", "message": "Error during login: type object 'datetime.datetime' has no attribute 'datetime'", "request_id": "de7f6a78-c1ff-4c7a-b230-2062d08357a0", "method": "POST", "path": "/api/auth/login", "remote_addr": "127.0.0.1", "user_agent": "Werkzeug/3.1.3"}
{"timestamp": "2025-04-29T21:56:58.491735", "level": "ERROR", "name": "auth_app", "message": "Error during login: type object 'datetime.datetime' has no attribute 'datetime'", "request_id": "15d6b0c5-9c1c-47c8-9058-353ddf1d0fde", "method": "POST", "path": "/api/auth/login", "remote_addr": "127.0.0.1", "user_agent": "Werkzeug/3.1.3"}
{"timestamp": "2025-04-29T21:56:59.880106", "level": "ERROR", "name": "auth_app", "message": "Error during login: type object 'datetime.datetime' has no attribute 'datetime'", "request_id": "d1eedcb9-fd61-41c1-8e72-24b40de8be1a", "method": "POST", "path": "/api/auth/login", "remote_addr": "127.0.0.1", "user_agent": "Werkzeug/3.1.3"}
{"timestamp": "2025-04-29T23:04:25.523807", "level": "ERROR", "name": "auth_app", "message": "Error during signup: (sqlite3.OperationalError) no such table: users\n[SQL: SELECT users.id AS users_id, users.email AS users_email, users.password AS users_password, users.failed_attempts AS users_failed_attempts, users.last_failed_attempt AS users_last_failed_attempt, users.created_at AS users_created_at, users.updated_at AS users_updated_at \nFROM users \nWHERE lower(users.email) LIKE lower(?)\n LIMIT ? OFFSET ?]\n[parameters: ('edwardkemper@gmail.com', 1, 0)]\n(Background on this error at: https://sqlalche.me/e/20/e3q8)", "request_id": "bd3a8bfe-5332-426a-b77c-b8972dc47848", "method": "POST", "path": "/api/auth/signup", "remote_addr": "192.168.65.1", "user_agent": "Mozilla/5.0 (Macintosh; Intel Mac OS X 10_15_7) AppleWebKit/537.36 (KHTML, like Gecko) Chrome/135.0.0.0 Safari/537.36"}
